Workbook

Sheet Pesca Nacional
B1: CLIENTES NACIONALES | T1: Calendario de Pago ($)
B2: Reserva | C2: Cliente | I2: Programa | J2: Programa | K2: Fecha | L2: Fecha Ejecucion | N2: Tarifa Programa (S/I) | T2: Abono Reserva (T-60/50%) | V2: Saldo Precio (T-30/50%) | X2: Pago 1 Real | AA2: Pago 2 Real | AD2: Pago 3 Real | AG2: Pago 4 Real | AJ2: Pago 5 Real | AM2: Pagado a la | AN2: Saldo | AO2: Saldo grupal
B3: Numero | C3: Grupo | D3: Nombre | E3: Email | F3: Confirmacion reserva | G3: Reserva confirmada | H3: Calendario | J3: noches | K3: reserva | L3: Check In | M3: Check Out | N3: Lista | O3: Comision o Descuento | P3: Monto $Descuento | Q3: Suplemento base o Non-Angler | R3: Bruto | S3: Liquido | T3: Fecha | U3: Monto | V3: Fecha | W3: Monto | X3: Fecha | Y3: Monto | Z3: Medio de pago | AA3: Fecha | AB3: Monto | AC3: Medio de pago | AD3: Fecha | AE3: Monto | AF3: Medio de pago | AG3: Fecha | AH3: Monto | AI3: Medio de pago | AJ3: Fecha | AK3: Monto | AL3: Medio de pago | AM3: Fecha | AN3: Adeudado | AO3: Adeudado
B4: 1 | C4: Rafael Loyola | D4: Jose luis Rodriguez casanueva | E4: rafael.loyoladominguez@gmail.com | F4: si | G4: si | H4: si | I4: Baker full | J4: =M4-L4 -> 4 | L4: 45995 | M4: 45999 | N4: =IF(J4=3,(1350000))+IF(J4=4,(1750000))+IF(J4=5,(2150000))+IF(J4=6,(2550000))+IF(J4=7,(2950000)) -> 1750000 | P4: =N4*O4 -> 0 | R4: =N4-P4+Q4 -> 1750000 | S4: =R4/1.19 -> 1470588.2 | T4: =+L4-60 -> 45935 | U4: =+R4/2 -> 875000 | V4: =+L4-30 -> 45965 | W4: =+U4 -> 875000 | X4: 45786 | Y4: 250000 | Z4: Transferencia | AA4: 45789 | AB4: 825000 | AC4: Transferencia | AM4: =Y4+AB4+AE4+AH4+AK4 -> 1075000 | AN4: =+R4-Y4-AB4-AE4-AH4 -> 675000 | AO4: =SUM(AN4:AN8) -> 4375000
B5: 2 | C5: Rafael Loyola | D5: Borja Rodriguez Rios | F5: si | G5: si | H5: si | I5: Baker full | J5: =M5-L5 -> 4 | L5: 45995 | M5: 45999 | N5: =IF(J5=3,(1350000))+IF(J5=4,(1750000))+IF(J5=5,(2150000))+IF(J5=6,(2550000))+IF(J5=7,(2950000)) -> 1750000 | P5: =N5*O5 -> 0 | R5: =N5-P5+Q5 -> 1750000 | S5: =R5/1.19 -> 1470588.2 | T5: =+L5-60 -> 45935 | U5: =+R5/2 -> 875000 | V5: =+L5-30 -> 45965 | W5: =+U5 -> 875000 | AA5: 45789 | AB5: 825000 | AC5: Transferencia | AM5: =Y5+AB5+AE5+AH5+AK5 -> 825000 | AN5: =+R5-Y5-AB5-AE5-AH5 -> 925000 | AO5: =CONCATENATE(IF(AP5<0,IF(AP5>-30,IF(AN5>0,"T",""),""),IF(AP5>0,IF(AN5>0,"DEUDA",""),"")))
A6: Total cañas nac. | B6: 3 | C6: Rafael Loyola | D6: Ignacio Rodiguez Rios | F6: si | G6: si | H6: si | I6: Baker full | J6: =M6-L6 -> 4 | L6: 45995 | M6: 45999 | N6: =IF(J6=3,(1350000))+IF(J6=4,(1750000))+IF(J6=5,(2150000))+IF(J6=6,(2550000))+IF(J6=7,(2950000)) -> 1750000 | P6: =N6*O6 -> 0 | R6: =N6-P6+Q6 -> 1750000 | S6: =R6/1.19 -> 1470588.2 | T6: =+L6-60 -> 45935 | U6: =+R6/2 -> 875000 | V6: =+L6-30 -> 45965 | W6: =+U6 -> 875000 | AA6: 45789 | AB6: 825000 | AC6: Transferencia | AM6: =Y6+AB6+AE6+AH6+AK6 -> 825000 | AN6: =+R6-Y6-AB6-AE6-AH6 -> 925000 | AO6: =CONCATENATE(IF(AP6<0,IF(AP6>-30,IF(AN6>0,"T",""),""),IF(AP6>0,IF(AN6>0,"DEUDA",""),"")))
A7: =COUNT(B4:B145) -> 129 | B7: 4 | C7: Rafael Loyola | D7: Cristian Fabres Ruiz | F7: si | G7: si | H7: si | I7: Baker full | J7: =M7-L7 -> 4 | L7: 45995 | M7: 45999 | N7: =IF(J7=3,(1350000))+IF(J7=4,(1750000))+IF(J7=5,(2150000))+IF(J7=6,(2550000))+IF(J7=7,(2950000)) -> 1750000 | P7: =N7*O7 -> 0 | R7: =N7-P7+Q7 -> 1750000 | S7: =R7/1.19 -> 1470588.2 | T7: =+L7-60 -> 45935 | U7: =+R7/2 -> 875000 | V7: =+L7-30 -> 45965 | W7: =+U7 -> 875000 | AA7: 45789 | AB7: 825000 | AC7: Transferencia | AM7: =Y7+AB7+AE7+AH7+AK7 -> 825000 | AN7: =+R7-Y7-AB7-AE7-AH7 -> 925000 | AO7: =CONCATENATE(IF(AP7<0,IF(AP7>-30,IF(AN7>0,"T",""),""),IF(AP7>0,IF(AN7>0,"DEUDA",""),"")))
B8: 5 | C8: Rafael Loyola | D8: Rafael Loyola Dominguez | F8: si | G8: si | H8: si | I8: Baker full | J8: =M8-L8 -> 4 | L8: 45995 | M8: 45999 | N8: =IF(J8=3,(1350000))+IF(J8=4,(1750000))+IF(J8=5,(2150000))+IF(J8=6,(2550000))+IF(J8=7,(2950000)) -> 1750000 | P8: =N8*O8 -> 0 | R8: =N8-P8+Q8 -> 1750000 | S8: =R8/1.19 -> 1470588.2 | T8: =+L8-60 -> 45935 | U8: =+R8/2 -> 875000 | V8: =+L8-30 -> 45965 | W8: =+U8 -> 875000 | AA8: 45789 | AB8: 825000 | AC8: Transferencia | AM8: =Y8+AB8+AE8+AH8+AK8 -> 825000 | AN8: =+R8-Y8-AB8-AE8-AH8 -> 925000 | AO8: =CONCATENATE(IF(AP8<0,IF(AP8>-30,IF(AN8>0,"T",""),""),IF(AP8>0,IF(AN8>0,"DEUDA",""),"")))
B9: 6 | C9: Diego Garcia | D9: Diego Garcia | E9: dgarcia@ddcorp.cl | F9: si | G9: si | H9: si | I9: Baker full | J9: =M9-L9 -> 3 | L9: 45981 | M9: 45984 | N9: =IF(J9=3,(1350000))+IF(J9=4,(1750000))+IF(J9=5,(2150000))+IF(J9=6,(2550000))+IF(J9=7,(2950000)) -> 1350000 | P9: =N9*O9 -> 0 | R9: =N9-P9+Q9 -> 1350000 | S9: =R9/1.19 -> 1134453.8 | T9: =+L9-60 -> 45921 | U9: =+R9/2 -> 675000 | V9: =+L9-30 -> 45951 | W9: =+U9 -> 675000 | X9: 45796 | Y9: 450000 | Z9: Webpay | AA9: 45811 | AB9: 666667 | AC9: Transferencia | AM9: =Y9+AB9+AE9+AH9+AK9 -> 1116667 | AN9: =+R9-Y9-AB9-AE9-AH9 -> 233333 | AO9: =SUM(AN9:AN11) -> 700001
A10: Total noches pesca nac. | B10: 7 | C10: Diego Garcia | D10: Borja García | F10: si | G10: si | H10: si | I10: Baker full | J10: =M10-L10 -> 3 | L10: 45981 | M10: 45984 | N10: =IF(J10=3,(1350000))+IF(J10=4,(1750000))+IF(J10=5,(2150000))+IF(J10=6,(2550000))+IF(J10=7,(2950000)) -> 1350000 | P10: =N10*O10 -> 0 | R10: =N10-P10+Q10 -> 1350000 | S10: =R10/1.19 -> 1134453.8 | T10: =+L10-60 -> 45921 | U10: =+R10/2 -> 675000 | V10: =+L10-30 -> 45951 | W10: =+U10 -> 675000 | X10: 45796 | Y10: 450000 | Z10: Webpay | AA10: 45811 | AB10: 666666 | AC10: Transferencia | AM10: =Y10+AB10+AE10+AH10+AK10 -> 1116666 | AN10: =+R10-Y10-AB10-AE10-AH10 -> 233334 | AO10: =CONCATENATE(IF(AP10<0,IF(AP10>-30,IF(AN10>0,"T",""),""),IF(AP10>0,IF(AN10>0,"DEUDA",""),"")))
A11: =SUM(J4:J168) -> 546 | B11: 8 | C11: Diego Garcia | D11: Beltrán García | F11: si | G11: si | H11: si | I11: Baker full | J11: =M11-L11 -> 3 | L11: 45981 | M11: 45984 | N11: =IF(J11=3,(1350000))+IF(J11=4,(1750000))+IF(J11=5,(2150000))+IF(J11=6,(2550000))+IF(J11=7,(2950000)) -> 1350000 | P11: =N11*O11 -> 0 | R11: =N11-P11+Q11 -> 1350000 | S11: =R11/1.19 -> 1134453.8 | T11: =+L11-60 -> 45921 | U11: =+R11/2 -> 675000 | V11: =+L11-30 -> 45951 | W11: =+U11 -> 675000 | X11: 45796 | Y11: 450000 | Z11: Webpay | AA11: 45811 | AB11: 666666 | AC11: Transferencia | AM11: =Y11+AB11+AE11+AH11+AK11 -> 1116666 | AN11: =+R11-Y11-AB11-AE11-AH11 -> 233334 | AO11: =CONCATENATE(IF(AP11<0,IF(AP11>-30,IF(AN11>0,"T",""),""),IF(AP11>0,IF(AN11>0,"DEUDA",""),"")))
B12: 9 | C12: Cesar Gavilan | D12: Cesar Gavilan | E12: ssavio11@gmail.com | F12: si | G12: si | H12: si | I12: Baker full | J12: =M12-L12 -> 4 | L12: 45959 | M12: 45963 | N12: 1600000 | P12: =N12*O12 -> 0 | R12: =N12-P12+Q12 -> 1600000 | S12: =R12/1.19 -> 1344537.8 | T12: =+L12-60 -> 45899 | U12: =+R12/2 -> 800000 | V12: =+L12-30 -> 45929 | W12: =+U12 -> 800000 | X12: 45718 | Y12: 1600000 | Z12: Transferencia | AM12: =Y12+AB12+AE12+AH12+AK12 -> 1600000 | AN12: =+R12-Y12-AB12-AE12-AH12 -> 0 | AO12: =SUM(AN12:AN13) -> 1600000
B13: 10 | C13: Cesar Gavilan | D13: Diego Gavilan | F13: si | G13: si | H13: si | I13: Baker full | J13: =M13-L13 -> 4 | L13: 45959 | M13: 45963 | N13: 1600000 | P13: =N13*O13 -> 0 | R13: =N13-P13+Q13 -> 1600000 | S13: =R13/1.19 -> 1344537.8 | T13: =+L13-60 -> 45899 | U13: =+R13/2 -> 800000 | V13: =+L13-30 -> 45929 | W13: =+U13 -> 800000 | AM13: =Y13+AB13+AE13+AH13+AK13 -> 0 | AN13: =+R13-Y13-AB13-AE13-AH13 -> 1600000 | AO13: =CONCATENATE(IF(AP13<0,IF(AP13>-30,IF(AN13>0,"T",""),""),IF(AP13>0,IF(AN13>0,"DEUDA",""),"")))
A14: Total noches PN temporada | B14: 11 | C14: JJ Dominguez | D14: Jorge Nazer | E14: juanjod1@gmail.com | F14: si | G14: si | H14: si | I14: Baker full | J14: =M14-L14 -> 4 | L14: 45973 | M14: 45977 | N14: 1600000 | O14: 0.2 | P14: =N14*O14 -> 320000 | R14: =N14-P14+Q14 -> 1280000 | S14: =R14/1.19 -> 1075630.3 | T14: =+L14-60 -> 45913 | U14: =+R14/2 -> 640000 | V14: =+L14-30 -> 45943 | W14: =+U14 -> 640000 | X14: 45594 | Y14: 450000 | Z14: Transferencia | AA14: 45698 | AB14: 300000 | AC14: Transferencia | AM14: =Y14+AB14+AE14+AH14+AK14 -> 750000 | AN14: =+R14-Y14-AB14-AE14-AH14 -> 530000 | AO14: =SUM(AN14:AN18) -> 3350000
A15: =J4+J9+J12+J14+J19+J21+J31+J33+J36+J40+J45+J48+J52+J55+J61+J63+J64+J68+J69+J70+J71+J73+J75+J78+J80+J82+J97+J98+J100+J101+J107+J108+J114+J116 -> 139 | B15: 12 | C15: JJ Dominguez | D15: Juan Jose Dominguez | F15: si | G15: si | H15: si | I15: Baker full | J15: =M15-L15 -> 4 | L15: 45973 | M15: 45977 | N15: 1750000 | O15: 0.2 | P15: =N15*O15 -> 350000 | R15: =N15-P15+Q15 -> 1400000 | S15: =R15/1.19 -> 1176470.6 | T15: =+L15-60 -> 45913 | U15: =+R15/2 -> 700000 | V15: =+L15-30 -> 45943 | W15: =+U15 -> 700000 | AM15: =Y40+AB40+AE15+AH15+AK15 -> 720000 | AN15: =+R15-Y40-AB40-AE15-AH15 -> 680000 | AO15: =CONCATENATE(IF(AP15<0,IF(AP15>-30,IF(AN15>0,"T",""),""),IF(AP15>0,IF(AN15>0,"DEUDA",""),"")))
B16: 13 | C16: JJ Dominguez | D16: Rodrigo Qchacovich | F16: si | G16: si | H16: si | I16: Baker full | J16: =M16-L16 -> 4 | L16: 45973 | M16: 45977 | N16: 1600000 | O16: 0.2 | P16: =N16*O16 -> 320000 | R16: =N16-P16+Q16 -> 1280000 | S16: =R16/1.19 -> 1075630.3 | T16: =+L16-60 -> 45913 | U16: =+R16/2 -> 640000 | V16: =+L16-30 -> 45943 | W16: =+U16 -> 640000 | X16: 45601 | Y16: 350000 | Z16: Transferencia | AA16: 45602 | AB16: 350000 | AC16: Transferencia | AM16: =Y16+AB16+AE16+AH16+AK16 -> 700000 | AN16: =+R16-Y16-AB16-AE16-AH16 -> 580000 | AO16: =CONCATENATE(IF(AP16<0,IF(AP16>-30,IF(AN16>0,"T",""),""),IF(AP16>0,IF(AN16>0,"DEUDA",""),"")))
B17: 14 | C17: JJ Dominguez | D17: Ignacio Bascuñan | F17: si | G17: si | H17: si | I17: Baker full | J17: =M17-L17 -> 4 | L17: 45973 | M17: 45977 | N17: 1600000 | O17: 0.2 | P17: =N17*O17 -> 320000 | R17: =N17-P17+Q17 -> 1280000 | S17: =R17/1.19 -> 1075630.3 | T17: =+L17-60 -> 45913 | U17: =+R17/2 -> 640000 | V17: =+L17-30 -> 45943 | W17: =+U17 -> 640000 | X17: 45614 | Y17: 350000 | Z17: Transferencia | AM17: =Y17+AB17+AE17+AH17+AK17 -> 350000 | AN17: =+R17-Y17-AB17-AE17-AH17 -> 930000 | AO17: =CONCATENATE(IF(AP17<0,IF(AP17>-30,IF(AN17>0,"T",""),""),IF(AP17>0,IF(AN17>0,"DEUDA",""),"")))
A18: Total bruto nac. | B18: 15 | C18: JJ Dominguez | D18: Jose Manuel Dominguez | F18: si | G18: si | H18: si | I18: Baker full | J18: =M18-L18 -> 4 | L18: 45973 | M18: 45977 | N18: 1600000 | O18: 0.2 | P18: =N18*O18 -> 320000 | R18: =N18-P18+Q18 -> 1280000 | S18: =R18/1.19 -> 1075630.3 | T18: =+L18-60 -> 45913 | U18: =+R18/2 -> 640000 | V18: =+L18-30 -> 45943 | W18: =+U18 -> 640000 | X18: 45615 | Y18: 250000 | Z18: Transferencia | AA18: 45925 | AB18: 400000 | AC18: Transferencia | AM18: =Y18+AB18+AE18+AH18+AK18 -> 650000 | AN18: =+R18-Y18-AB18-AE18-AH18 -> 630000 | AO18: =CONCATENATE(IF(AP18<0,IF(AP18>-30,IF(AN18>0,"T",""),""),IF(AP18>0,IF(AN18>0,"DEUDA",""),"")))
A19: =SUM(R4:R145) -> 208347000 | B19: 16 | C19: Grupo Alex Bratz | D19: Alex Bratz | J19: =M19-L19 -> 4 | L19: 46081 | M19: 46085 | N19: 1600000 | P19: =N19*O19 -> 0 | R19: =N19-P19+Q19 -> 1600000 | S19: =R19/1.19 -> 1344537.8 | T19: =+L19-60 -> 46021 | U19: =+R19/2 -> 800000 | V19: =+L19-30 -> 46051 | W19: =+U19 -> 800000 | X19: 45663 | Y19: 1000000 | Z19: Transferencia | AA19: 46077 | AB19: 600000 | AC19: Transferencia | AM19: =Y19+AB19+AE19+AH19+AK19 -> 1600000 | AN19: =+R19-Y19-AB19-AE19-AH19 -> 0 | AO19: =CONCATENATE(IF(AP19<0,IF(AP19>-30,IF(AN19>0,"T",""),""),IF(AP19>0,IF(AN19>0,"DEUDA",""),"")))
B20: 17 | C20: Grupo Alex Bratz | J20: =M20-L20 -> 4 | L20: 46081 | M20: 46085 | N20: 1600000 | P20: =N20*O20 -> 0 | R20: =N20-P20+Q20 -> 1600000 | S20: =R20/1.19 -> 1344537.8 | T20: =+L20-60 -> 46021 | U20: =+R20/2 -> 800000 | V20: =+L20-30 -> 46051 | W20: =+U20 -> 800000 | X20: 46045 | Y20: 1000000 | Z20: Trasnferencia | AA20: 46077 | AB20: 600000 | AC20: Transferencia | AM20: =Y20+AB20+AE20+AH20+AK20 -> 1600000 | AN20: =+R20-Y20-AB20-AE20-AH20 -> 0 | AO20: =CONCATENATE(IF(AP20<0,IF(AP20>-30,IF(AN20>0,"T",""),""),IF(AP20>0,IF(AN20>0,"DEUDA",""),"")))
B21: 18 | C21: Grupo Santolaya | E21: gonzalo@deisa.cl | F21: si | H21: si | I21: Baker full | J21: =M21-L21 -> 3 | L21: 46006 | M21: 46009 | N21: =IF(J21=3,(1350000))+IF(J21=4,(1750000))+IF(J21=5,(2150000))+IF(J21=6,(2550000))+IF(J21=7,(2950000)) -> 1350000 | O21: 0.1 | P21: =N21*O21 -> 135000 | R21: =N21-P21+Q21 -> 1215000 | S21: =R21/1.19 -> 1021008.4 | T21: =+L21-60 -> 45946 | U21: =+R21/2 -> 607500 | V21: =+L21-30 -> 45976 | W21: =+U21 -> 607500 | AM21: =Y21+AB21+AE21+AH21+AK21 -> 0 | AN21: =+R21-Y21-AB21-AE21-AH21 -> 1215000 | AO21: =SUM(AN21:AN30) -> 12150000
A22: Total liquido nac. | B22: 19 | C22: Grupo Santolaya | F22: si | H22: si | I22: Baker full | J22: =M22-L22 -> 3 | L22: 46006 | M22: 46009 | N22: =IF(J22=3,(1350000))+IF(J22=4,(1750000))+IF(J22=5,(2150000))+IF(J22=6,(2550000))+IF(J22=7,(2950000)) -> 1350000 | O22: 0.1 | P22: =N22*O22 -> 135000 | R22: =N22-P22+Q22 -> 1215000 | S22: =R22/1.19 -> 1021008.4 | T22: =+L22-60 -> 45946 | U22: =+R22/2 -> 607500 | V22: =+L22-30 -> 45976 | W22: =+U22 -> 607500 | AM22: =Y22+AB22+AE22+AH22+AK22 -> 0 | AN22: =+R22-Y22-AB22-AE22-AH22 -> 1215000 | AO22: =CONCATENATE(IF(AP22<0,IF(AP22>-30,IF(AN22>0,"T",""),""),IF(AP22>0,IF(AN22>0,"DEUDA",""),"")))
A23: =SUM(S4:S145) -> 1.7508151e+08 | B23: 20 | C23: Grupo Santolaya | F23: si | H23: si | I23: Baker full | J23: =M23-L23 -> 3 | L23: 46006 | M23: 46009 | N23: =IF(J23=3,(1350000))+IF(J23=4,(1750000))+IF(J23=5,(2150000))+IF(J23=6,(2550000))+IF(J23=7,(2950000)) -> 1350000 | O23: 0.1 | P23: =N23*O23 -> 135000 | R23: =N23-P23+Q23 -> 1215000 | S23: =R23/1.19 -> 1021008.4 | T23: =+L23-60 -> 45946 | U23: =+R23/2 -> 607500 | V23: =+L23-30 -> 45976 | W23: =+U23 -> 607500 | AM23: =Y23+AB23+AE23+AH23+AK23 -> 0 | AN23: =+R23-Y23-AB23-AE23-AH23 -> 1215000 | AO23: =CONCATENATE(IF(AP23<0,IF(AP23>-30,IF(AN23>0,"T",""),""),IF(AP23>0,IF(AN23>0,"DEUDA",""),"")))
B24: 21 | C24: Grupo Santolaya | F24: si | H24: si | I24: Baker full | J24: =M24-L24 -> 3 | L24: 46006 | M24: 46009 | N24: =IF(J24=3,(1350000))+IF(J24=4,(1750000))+IF(J24=5,(2150000))+IF(J24=6,(2550000))+IF(J24=7,(2950000)) -> 1350000 | O24: 0.1 | P24: =N24*O24 -> 135000 | R24: =N24-P24+Q24 -> 1215000 | S24: =R24/1.19 -> 1021008.4 | T24: =+L24-60 -> 45946 | U24: =+R24/2 -> 607500 | V24: =+L24-30 -> 45976 | W24: =+U24 -> 607500 | AM24: =Y24+AB24+AE24+AH24+AK24 -> 0 | AN24: =+R24-Y24-AB24-AE24-AH24 -> 1215000 | AO24: =CONCATENATE(IF(AP24<0,IF(AP24>-30,IF(AN24>0,"T",""),""),IF(AP24>0,IF(AN24>0,"DEUDA",""),"")))
B25: 22 | C25: Grupo Santolaya | F25: si | H25: si | I25: Baker full | J25: =M25-L25 -> 3 | L25: 46006 | M25: 46009 | N25: =IF(J25=3,(1350000))+IF(J25=4,(1750000))+IF(J25=5,(2150000))+IF(J25=6,(2550000))+IF(J25=7,(2950000)) -> 1350000 | O25: 0.1 | P25: =N25*O25 -> 135000 | R25: =N25-P25+Q25 -> 1215000 | S25: =R25/1.19 -> 1021008.4 | T25: =+L25-60 -> 45946 | U25: =+R25/2 -> 607500 | V25: =+L25-30 -> 45976 | W25: =+U25 -> 607500 | AM25: =Y25+AB25+AE25+AH25+AK25 -> 0 | AN25: =+R25-Y25-AB25-AE25-AH25 -> 1215000 | AO25: =CONCATENATE(IF(AP25<0,IF(AP25>-30,IF(AN25>0,"T",""),""),IF(AP25>0,IF(AN25>0,"DEUDA",""),"")))
A26: Monto pagado a | B26: 23 | C26: Grupo Santolaya | F26: si | H26: si | I26: Baker full | J26: =M26-L26 -> 3 | L26: 46006 | M26: 46009 | N26: =IF(J26=3,(1350000))+IF(J26=4,(1750000))+IF(J26=5,(2150000))+IF(J26=6,(2550000))+IF(J26=7,(2950000)) -> 1350000 | O26: 0.1 | P26: =N26*O26 -> 135000 | R26: =N26-P26+Q26 -> 1215000 | S26: =R26/1.19 -> 1021008.4 | T26: =+L26-60 -> 45946 | U26: =+R26/2 -> 607500 | V26: =+L26-30 -> 45976 | W26: =+U26 -> 607500 | AM26: =Y26+AB26+AE26+AH26+AK26 -> 0 | AN26: =+R26-Y26-AB26-AE26-AH26 -> 1215000 | AO26: =CONCATENATE(IF(AP26<0,IF(AP26>-30,IF(AN26>0,"T",""),""),IF(AP26>0,IF(AN26>0,"DEUDA",""),"")))
A27: =TODAY() -> 46183 | B27: 24 | C27: Grupo Santolaya | F27: si | H27: si | I27: Baker full | J27: =M27-L27 -> 3 | L27: 46006 | M27: 46009 | N27: =IF(J27=3,(1350000))+IF(J27=4,(1750000))+IF(J27=5,(2150000))+IF(J27=6,(2550000))+IF(J27=7,(2950000)) -> 1350000 | O27: 0.1 | P27: =N27*O27 -> 135000 | R27: =N27-P27+Q27 -> 1215000 | S27: =R27/1.19 -> 1021008.4 | T27: =+L27-60 -> 45946 | U27: =+R27/2 -> 607500 | V27: =+L27-30 -> 45976 | W27: =+U27 -> 607500 | AM27: =Y27+AB27+AE27+AH27+AK27 -> 0 | AN27: =+R27-Y27-AB27-AE27-AH27 -> 1215000 | AO27: =CONCATENATE(IF(AP27<0,IF(AP27>-30,IF(AN27>0,"T",""),""),IF(AP27>0,IF(AN27>0,"DEUDA",""),"")))
A28: =SUM(AM4:AM137) -> 68424999 | B28: 25 | C28: Grupo Santolaya | F28: si | H28: si | I28: Baker full | J28: =M28-L28 -> 3 | L28: 46006 | M28: 46009 | N28: =IF(J28=3,(1350000))+IF(J28=4,(1750000))+IF(J28=5,(2150000))+IF(J28=6,(2550000))+IF(J28=7,(2950000)) -> 1350000 | O28: 0.1 | P28: =N28*O28 -> 135000 | R28: =N28-P28+Q28 -> 1215000 | S28: =R28/1.19 -> 1021008.4 | T28: =+L28-60 -> 45946 | U28: =+R28/2 -> 607500 | V28: =+L28-30 -> 45976 | W28: =+U28 -> 607500 | AM28: =Y28+AB28+AE28+AH28+AK28 -> 0 | AN28: =+R28-Y28-AB28-AE28-AH28 -> 1215000 | AO28: =CONCATENATE(IF(AP28<0,IF(AP28>-30,IF(AN28>0,"T",""),""),IF(AP28>0,IF(AN28>0,"DEUDA",""),"")))
B29: 26 | C29: Grupo Santolaya | F29: si | H29: si | I29: Baker full | J29: =M29-L29 -> 3 | L29: 46006 | M29: 46009 | N29: =IF(J29=3,(1350000))+IF(J29=4,(1750000))+IF(J29=5,(2150000))+IF(J29=6,(2550000))+IF(J29=7,(2950000)) -> 1350000 | O29: 0.1 | P29: =N29*O29 -> 135000 | R29: =N29-P29+Q29 -> 1215000 | S29: =R29/1.19 -> 1021008.4 | T29: =+L29-60 -> 45946 | U29: =+R29/2 -> 607500 | V29: =+L29-30 -> 45976 | W29: =+U29 -> 607500 | AM29: =Y29+AB29+AE29+AH29+AK29 -> 0 | AN29: =+R29-Y29-AB29-AE29-AH29 -> 1215000 | AO29: =CONCATENATE(IF(AP29<0,IF(AP29>-30,IF(AN29>0,"T",""),""),IF(AP29>0,IF(AN29>0,"DEUDA",""),"")))
B30: 27 | C30: Grupo Santolaya | F30: si | H30: si | I30: Baker full | J30: =M30-L30 -> 3 | L30: 46006 | M30: 46009 | N30: =IF(J30=3,(1350000))+IF(J30=4,(1750000))+IF(J30=5,(2150000))+IF(J30=6,(2550000))+IF(J30=7,(2950000)) -> 1350000 | O30: 0.1 | P30: =N30*O30 -> 135000 | R30: =N30-P30+Q30 -> 1215000 | S30: =R30/1.19 -> 1021008.4 | T30: =+L30-60 -> 45946 | U30: =+R30/2 -> 607500 | V30: =+L30-30 -> 45976 | W30: =+U30 -> 607500 | AM30: =Y30+AB30+AE30+AH30+AK30 -> 0 | AN30: =+R30-Y30-AB30-AE30-AH30 -> 1215000 | AO30: =CONCATENATE(IF(AP30<0,IF(AP30>-30,IF(AN30>0,"T",""),""),IF(AP30>0,IF(AN30>0,"DEUDA",""),"")))
A31: Monto adeudado a | B31: 28 | C31: Grupo Santolaya | E31: gonzalo@deisa.cl | F31: si | H31: si | I31: Baker full | J31: =M31-L31 -> 5 | L31: 45979 | M31: 45984 | N31: =IF(J31=3,(1350000))+IF(J31=4,(1750000))+IF(J31=5,(2150000))+IF(J31=6,(2550000))+IF(J31=7,(2950000)) -> 2150000 | O31: 0.1 | P31: =N31*O31 -> 215000 | R31: =N31-P31+Q31 -> 1935000 | S31: =R31/1.19 -> 1626050.4 | T31: =+L31-60 -> 45919 | U31: =+R31/2 -> 967500 | V31: =+L31-30 -> 45949 | W31: =+U31 -> 967500 | AM31: =Y31+AB31+AE31+AH31+AK31 -> 0 | AN31: =+R31-Y31-AB31-AE31-AH31 -> 1935000 | AO31: =SUM(AN31:AN32) -> 3870000
A32: =A27 -> 46183 | B32: 29 | C32: Grupo Santolaya | F32: si | H32: si | I32: Baker full | J32: =M32-L32 -> 5 | L32: 45979 | M32: 45984 | N32: =IF(J32=3,(1350000))+IF(J32=4,(1750000))+IF(J32=5,(2150000))+IF(J32=6,(2550000))+IF(J32=7,(2950000)) -> 2150000 | O32: 0.1 | P32: =N32*O32 -> 215000 | R32: =N32-P32+Q32 -> 1935000 | S32: =R32/1.19 -> 1626050.4 | T32: =+L32-60 -> 45919 | U32: =+R32/2 -> 967500 | V32: =+L32-30 -> 45949 | W32: =+U32 -> 967500 | AM32: =Y32+AB32+AE32+AH32+AK32 -> 0 | AN32: =+R32-Y32-AB32-AE32-AH32 -> 1935000 | AO32: =CONCATENATE(IF(AP32<0,IF(AP32>-30,IF(AN32>0,"T",""),""),IF(AP32>0,IF(AN32>0,"DEUDA",""),"")))
A33: =SUM(AN4:AN137) -> 132427001 | B33: 30 | C33: Grupo Dieguez | D33: Juan dieguez jr | E33: Jdieguez@hidrosan.cl | F33: si | G33: si | H33: si | I33: Baker full | J33: =M33-L33 -> 4 | L33: 45981 | M33: 45985 | N33: =IF(J33=3,(1350000))+IF(J33=4,(1750000))+IF(J33=5,(2150000))+IF(J33=6,(2550000))+IF(J33=7,(2950000)) -> 1750000 | O33: 0.25 | P33: =N33*O33 -> 437500 | R33: =N33-P33+Q33 -> 1312500 | S33: =R33/1.19 -> 1102941.2 | T33: =+L33-60 -> 45921 | U33: =+R33/2 -> 656250 | V33: =+L33-30 -> 45951 | W33: =+U33 -> 656250 | X33: 45930 | Y33: 656250 | Z33: Transferencia | AM33: =Y33+AB33+AE33+AH33+AK33 -> 656250 | AN33: =+R33-Y33-AB33-AE33-AH33 -> 656250 | AO33: =SUM(AN33:AN35) -> 2200000
B34: 31 | C34: Grupo Dieguez | D34: Juan dieguez SR | F34: si | G34: si | H34: si | I34: Baker full | J34: =M34-L34 -> 4 | L34: 45981 | M34: 45985 | N34: =IF(J34=3,(1350000))+IF(J34=4,(1750000))+IF(J34=5,(2150000))+IF(J34=6,(2550000))+IF(J34=7,(2950000)) -> 1750000 | O34: 0.25 | P34: =N34*O34 -> 437500 | R34: =N34-P34+Q34 -> 1312500 | S34: =R34/1.19 -> 1102941.2 | T34: =+L34-60 -> 45921 | U34: =+R34/2 -> 656250 | V34: =+L34-30 -> 45951 | W34: =+U34 -> 656250 | X34: 45930 | Y34: 656250 | Z34: Transferencia | AM34: =Y34+AB34+AE34+AH34+AK34 -> 656250 | AN34: =+R34-Y34-AB34-AE34-AH34 -> 656250 | AO34: =CONCATENATE(IF(AP34<0,IF(AP34>-30,IF(AN34>0,"T",""),""),IF(AP34>0,IF(AN34>0,"DEUDA",""),"")))
B35: 32 | C35: Grupo Dieguez | D35: Ricardo garif | F35: si | G35: si | H35: si | I35: Baker single | J35: =M35-L35 -> 4 | L35: 45981 | M35: 45985 | N35: 2450000 | O35: 0.25 | P35: =N35*O35 -> 612500 | R35: =N35-P35+Q35 -> 1837500 | S35: =R35/1.19 -> 1544117.6 | T35: =+L35-60 -> 45921 | U35: =+R35/2 -> 918750 | V35: =+L35-30 -> 45951 | W35: =+U35 -> 918750 | X35: 45928 | Y35: 950000 | Z35: Webpay | AM35: =Y35+AB35+AE35+AH35+AK35 -> 950000 | AN35: =+R35-Y35-AB35-AE35-AH35 -> 887500 | AO35: =CONCATENATE(IF(AP35<0,IF(AP35>-30,IF(AN35>0,"T",""),""),IF(AP35>0,IF(AN35>0,"DEUDA",""),"")))
B36: 33 | C36: Grupo Perez | D36: Tomas Perez | E36: tomasperezjarpa@gmail.com | F36: si | G36: si | H36: si | I36: Baker full | J36: =M36-L36 -> 3 | L36: 45981 | M36: 45984 | N36: =IF(J36=3,(1350000))+IF(J36=4,(1750000))+IF(J36=5,(2150000))+IF(J36=6,(2550000))+IF(J36=7,(2950000)) -> 1350000 | O36: 0.15 | P36: =N36*O36 -> 202500 | R36: =N36-P36+Q36 -> 1147500 | S36: =R36/1.19 -> 964285.71 | T36: =+L36-60 -> 45921 | U36: =+R36/2 -> 573750 | V36: =+L36-30 -> 45951 | W36: =+U36 -> 573750 | X36: 45852 | Y36: 573750 | Z36: Webpay | AA36: 46323 | AB36: 573750 | AC36: Transferencia | AM36: =Y36+AB36+AE36+AH36+AK36 -> 1147500 | AN36: =+R36-Y36-AB36-AE36-AH36 -> 0 | AO36: =SUM(AN36:AN39) -> 0
B37: 34 | C37: Grupo Perez | D37: GERARDO PEREZ | F37: si | G37: si | H37: si | I37: Baker full | J37: =M37-L37 -> 3 | L37: 45981 | M37: 45984 | N37: =IF(J37=3,(1350000))+IF(J37=4,(1750000))+IF(J37=5,(2150000))+IF(J37=6,(2550000))+IF(J37=7,(2950000)) -> 1350000 | O37: 0.15 | P37: =N37*O37 -> 202500 | R37: =N37-P37+Q37 -> 1147500 | S37: =R37/1.19 -> 964285.71 | T37: =+L37-60 -> 45921 | U37: =+R37/2 -> 573750 | V37: =+L37-30 -> 45951 | W37: =+U37 -> 573750 | X37: 45852 | Y37: 1147500 | Z37: Webpay | AM37: =Y37+AB37+AE37+AH37+AK37 -> 1147500 | AN37: =+R37-Y37-AB37-AE37-AH37 -> 0 | AO37: =CONCATENATE(IF(AP37<0,IF(AP37>-30,IF(AN37>0,"T",""),""),IF(AP37>0,IF(AN37>0,"DEUDA",""),"")))
B38: 35 | C38: Grupo Perez | D38: GONZALO RUSSI | F38: si | G38: si | H38: si | I38: Baker full | J38: =M38-L38 -> 3 | L38: 45981 | M38: 45984 | N38: =IF(J38=3,(1350000))+IF(J38=4,(1750000))+IF(J38=5,(2150000))+IF(J38=6,(2550000))+IF(J38=7,(2950000)) -> 1350000 | O38: 0.15 | P38: =N38*O38 -> 202500 | R38: =N38-P38+Q38 -> 1147500 | S38: =R38/1.19 -> 964285.71 | T38: =+L38-60 -> 45921 | U38: =+R38/2 -> 573750 | V38: =+L38-30 -> 45951 | W38: =+U38 -> 573750 | X38: 45852 | Y38: 573750 | Z38: Webpay | AA38: 45959 | AB38: 573750 | AC38: webpay | AM38: =Y38+AB38+AE38+AH38+AK38 -> 1147500 | AN38: =+R38-Y38-AB38-AE38-AH38 -> 0 | AO38: =CONCATENATE(IF(AP38<0,IF(AP38>-30,IF(AN38>0,"T",""),""),IF(AP38>0,IF(AN38>0,"DEUDA",""),"")))
B39: 36 | C39: Grupo Perez | D39: ENRIQUE RUSSI | F39: si | G39: si | H39: si | I39: Baker full | J39: =M39-L39 -> 3 | L39: 45981 | M39: 45984 | N39: =IF(J39=3,(1350000))+IF(J39=4,(1750000))+IF(J39=5,(2150000))+IF(J39=6,(2550000))+IF(J39=7,(2950000)) -> 1350000 | O39: 0.15 | P39: =N39*O39 -> 202500 | R39: =N39-P39+Q39 -> 1147500 | S39: =R39/1.19 -> 964285.71 | T39: =+L39-60 -> 45921 | U39: =+R39/2 -> 573750 | V39: =+L39-30 -> 45951 | W39: =+U39 -> 573750 | X39: 45852 | Y39: 573750 | Z39: Webpay | AA39: 45959 | AB39: 573750 | AC39: webpay | AM39: =Y39+AB39+AE39+AH39+AK39 -> 1147500 | AN39: =+R39-Y39-AB39-AE39-AH39 -> 0 | AO39: =CONCATENATE(IF(AP39<0,IF(AP39>-30,IF(AN39>0,"T",""),""),IF(AP39>0,IF(AN39>0,"DEUDA",""),"")))
B40: 37 | C40: Grupo dieguez - dominguez | D40: Juango Domingues | E40: Jdieguez@hidrosan.cl | F40: si | H40: si | I40: Baker full | J40: =M40-L40 -> 4 | L40: 45946 | M40: 45950 | N40: 1600000 | O40: 0.25 | P40: =N40*O40 -> 400000 | R40: =N40-P40+Q40 -> 1200000 | S40: =R40/1.19 -> 1008403.4 | T40: =+L40-60 -> 45886 | U40: =+R40/2 -> 600000 | V40: =+L40-30 -> 45916 | W40: =+U40 -> 600000 | X40: 45575 | Y40: 250000 | Z40: Transferencia | AA40: 45582 | AB40: 470000 | AC40: Transferencia | AD40: 45914 | AE40: 480000 | AF40: Trasnferencia | AM40: =Y40+AB40+AE40+AH40+AK40 -> 1200000 | AN40: =+R40-Y40-AB40-AE40-AH40 -> 0 | AO40: =SUM(AN40:AN44) -> 1968750
...

Sheet Negocios
A1: CLIENTES NACIONALES | P1: Calendario de Pago ($)
A2: Reserva | B2: Cliente | F2: Programa | G2: Fecha | H2: Fecha Ejecucion | J2: Tarifa Programa (S/I) | P2: Abono Reserva (T-60/50%) | R2: Saldo Precio (T-30/50%) | T2: Pago 1 Real | W2: Pago 2 Real | Z2: Pago 3 Real | AC2: Pago 4 Real | AF2: Pagado a la | AG2: Saldo
A3: Numero | B3: Grupo | C3: Codigo Cloudbeds | D3: nombre | E3: RUT | F3: noches | G3: reserva | H3: Check In | I3: Check Out | J3: Lista | K3: Comision o Descuento | L3: Monto $Descuento | M3: Suplemento base o Non-Angler | N3: Bruto | O3: Liquido | P3: Fecha | Q3: Monto | R3: Fecha | S3: Monto | T3: Fecha | U3: Monto | V3: Medio de pago | W3: Fecha | X3: Monto | Y3: Medio de pago | Z3: Fecha | AA3: Monto | AB3: Medio de pago | AC3: Fecha | AD3: Monto | AE3: Medio de pago | AF3: Fecha | AG3: Adeudao | AI3: =TODAY() -> 46183
A4: 1 | B4: Grupo Dieguez | F4: =I4-H4 -> 5 | H4: 45744 | I4: 45749 | J4: =IF(F4=3,(1225000))+IF(F4=4,(1600000))+IF(F4=5,(1975000))+IF(F4=6,(2350000))+IF(F4=7,(2725000)) -> 1975000 | L4: =J4*K4 -> 0 | N4: =J4-L4+M4 -> 1975000 | O4: =N4/1.19 -> 1659663.9 | P4: =+H4-60 -> 45684 | Q4: =+N4/2 -> 987500 | R4: =+H4-30 -> 45714 | S4: =+Q4 -> 987500 | AF4: =U4+X4+AA4+AD4 -> 0 | AG4: =+N4-U4-X4-AA4-AD4 -> 1975000 | AH4: =CONCATENATE(IF(AI4<0,IF(AI4>-30,IF(AG4>0,"T",""),""),IF(AI4>0,IF(AG4>0,"DEUDA",""),""))) | AI4: ='Pesca Nacional'!$AP$3-H4 -> -45744
A5: 2 | B5: Grupo Dieguez | F5: =I5-H5 -> 5 | H5: 45744 | I5: 45749 | J5: =IF(F5=3,(1225000))+IF(F5=4,(1600000))+IF(F5=5,(1975000))+IF(F5=6,(2350000))+IF(F5=7,(2725000)) -> 1975000 | L5: =J5*K5 -> 0 | N5: =J5-L5+M5 -> 1975000 | O5: =N5/1.19 -> 1659663.9 | P5: =+H5-60 -> 45684 | Q5: =+N5/2 -> 987500 | R5: =+H5-30 -> 45714 | S5: =+Q5 -> 987500 | AF5: =U5+X5+AA5+AD5 -> 0 | AG5: =+N5-U5-X5-AA5-AD5 -> 1975000 | AH5: =CONCATENATE(IF(AI5<0,IF(AI5>-30,IF(AG5>0,"T",""),""),IF(AI5>0,IF(AG5>0,"DEUDA",""),""))) | AI5: ='Pesca Nacional'!$AP$3-H5 -> -45744
A6: 3 | B6: Grupo Dieguez | F6: =I6-H6 -> 5 | H6: 45744 | I6: 45749 | J6: =IF(F6=3,(1225000))+IF(F6=4,(1600000))+IF(F6=5,(1975000))+IF(F6=6,(2350000))+IF(F6=7,(2725000)) -> 1975000 | L6: =J6*K6 -> 0 | N6: =J6-L6+M6 -> 1975000 | O6: =N6/1.19 -> 1659663.9 | P6: =+H6-60 -> 45684 | Q6: =+N6/2 -> 987500 | R6: =+H6-30 -> 45714 | S6: =+Q6 -> 987500 | AF6: =U6+X6+AA6+AD6 -> 0 | AG6: =+N6-U6-X6-AA6-AD6 -> 1975000 | AH6: =CONCATENATE(IF(AI6<0,IF(AI6>-30,IF(AG6>0,"T",""),""),IF(AI6>0,IF(AG6>0,"DEUDA",""),""))) | AI6: ='Pesca Nacional'!$AP$3-H6 -> -45744
A7: 4 | B7: Grupo Dieguez | F7: =I7-H7 -> 5 | H7: 45744 | I7: 45749 | J7: =IF(F7=3,(1225000))+IF(F7=4,(1600000))+IF(F7=5,(1975000))+IF(F7=6,(2350000))+IF(F7=7,(2725000)) -> 1975000 | L7: =J7*K7 -> 0 | N7: =J7-L7+M7 -> 1975000 | O7: =N7/1.19 -> 1659663.9 | P7: =+H7-60 -> 45684 | Q7: =+N7/2 -> 987500 | R7: =+H7-30 -> 45714 | S7: =+Q7 -> 987500 | AF7: =U7+X7+AA7+AD7 -> 0 | AG7: =+N7-U7-X7-AA7-AD7 -> 1975000 | AH7: =CONCATENATE(IF(AI7<0,IF(AI7>-30,IF(AG7>0,"T",""),""),IF(AI7>0,IF(AG7>0,"DEUDA",""),""))) | AI7: ='Pesca Nacional'!$AP$3-H7 -> -45744
A8: 5 | B8: Grupo Dieguez | F8: =I8-H8 -> 5 | H8: 45744 | I8: 45749 | J8: =IF(F8=3,(1225000))+IF(F8=4,(1600000))+IF(F8=5,(1975000))+IF(F8=6,(2350000))+IF(F8=7,(2725000)) -> 1975000 | L8: =J8*K8 -> 0 | N8: =J8-L8+M8 -> 1975000 | O8: =N8/1.19 -> 1659663.9 | P8: =+H8-60 -> 45684 | Q8: =+N8/2 -> 987500 | R8: =+H8-30 -> 45714 | S8: =+Q8 -> 987500 | AF8: =U8+X8+AA8+AD8 -> 0 | AG8: =+N8-U8-X8-AA8-AD8 -> 1975000 | AH8: =CONCATENATE(IF(AI8<0,IF(AI8>-30,IF(AG8>0,"T",""),""),IF(AI8>0,IF(AG8>0,"DEUDA",""),""))) | AI8: ='Pesca Nacional'!$AP$3-H8 -> -45744
A9: 6 | B9: Grupo Andes otoño | F9: =I9-H9 -> 4 | H9: 45729 | I9: 45733 | J9: =IF(F9=3,(1225000))+IF(F9=4,(1600000))+IF(F9=5,(1975000))+IF(F9=6,(2350000))+IF(F9=7,(2725000)) -> 1600000 | L9: =J9*K9 -> 0 | N9: =J9-L9+M9 -> 1600000 | O9: =N9/1.19 -> 1344537.8 | P9: =+H9-60 -> 45669 | Q9: =+N9/2 -> 800000 | R9: =+H9-30 -> 45699 | S9: =+Q9 -> 800000 | AF9: =U9+X9+AA9+AD9 -> 0 | AG9: =+N9-U9-X9-AA9-AD9 -> 1600000 | AH9: =CONCATENATE(IF(AI9<0,IF(AI9>-30,IF(AG9>0,"T",""),""),IF(AI9>0,IF(AG9>0,"DEUDA",""),""))) | AI9: ='Pesca Nacional'!$AP$3-H9 -> -45729
A10: 7 | B10: Grupo Andes otoño | F10: =I10-H10 -> 4 | H10: 45729 | I10: 45733 | J10: =IF(F10=3,(1225000))+IF(F10=4,(1600000))+IF(F10=5,(1975000))+IF(F10=6,(2350000))+IF(F10=7,(2725000)) -> 1600000 | L10: =J10*K10 -> 0 | N10: =J10-L10+M10 -> 1600000 | O10: =N10/1.19 -> 1344537.8 | P10: =+H10-60 -> 45669 | Q10: =+N10/2 -> 800000 | R10: =+H10-30 -> 45699 | S10: =+Q10 -> 800000 | AF10: =U10+X10+AA10+AD10 -> 0 | AG10: =+N10-U10-X10-AA10-AD10 -> 1600000 | AH10: =CONCATENATE(IF(AI10<0,IF(AI10>-30,IF(AG10>0,"T",""),""),IF(AI10>0,IF(AG10>0,"DEUDA",""),""))) | AI10: ='Pesca Nacional'!$AP$3-H10 -> -45729
A11: 8 | B11: Grupo Andes otoño | F11: =I11-H11 -> 4 | H11: 45729 | I11: 45733 | J11: =IF(F11=3,(1225000))+IF(F11=4,(1600000))+IF(F11=5,(1975000))+IF(F11=6,(2350000))+IF(F11=7,(2725000)) -> 1600000 | L11: =J11*K11 -> 0 | N11: =J11-L11+M11 -> 1600000 | O11: =N11/1.19 -> 1344537.8 | P11: =+H11-60 -> 45669 | Q11: =+N11/2 -> 800000 | R11: =+H11-30 -> 45699 | S11: =+Q11 -> 800000 | AF11: =U11+X11+AA11+AD11 -> 0 | AG11: =+N11-U11-X11-AA11-AD11 -> 1600000 | AH11: =CONCATENATE(IF(AI11<0,IF(AI11>-30,IF(AG11>0,"T",""),""),IF(AI11>0,IF(AG11>0,"DEUDA",""),""))) | AI11: ='Pesca Nacional'!$AP$3-H11 -> -45729
A12: 9 | B12: Grupo Andes otoño | F12: =I12-H12 -> 4 | H12: 45729 | I12: 45733 | J12: =IF(F12=3,(1225000))+IF(F12=4,(1600000))+IF(F12=5,(1975000))+IF(F12=6,(2350000))+IF(F12=7,(2725000)) -> 1600000 | L12: =J12*K12 -> 0 | N12: =J12-L12+M12 -> 1600000 | O12: =N12/1.19 -> 1344537.8 | P12: =+H12-60 -> 45669 | Q12: =+N12/2 -> 800000 | R12: =+H12-30 -> 45699 | S12: =+Q12 -> 800000 | AF12: =U12+X12+AA12+AD12 -> 0 | AG12: =+N12-U12-X12-AA12-AD12 -> 1600000 | AH12: =CONCATENATE(IF(AI12<0,IF(AI12>-30,IF(AG12>0,"T",""),""),IF(AI12>0,IF(AG12>0,"DEUDA",""),""))) | AI12: ='Pesca Nacional'!$AP$3-H12 -> -45729
A13: 10 | B13: Grupo Andes otoño | F13: =I13-H13 -> 4 | H13: 45729 | I13: 45733 | J13: =IF(F13=3,(1225000))+IF(F13=4,(1600000))+IF(F13=5,(1975000))+IF(F13=6,(2350000))+IF(F13=7,(2725000)) -> 1600000 | L13: =J13*K13 -> 0 | N13: =J13-L13+M13 -> 1600000 | O13: =N13/1.19 -> 1344537.8 | P13: =+H13-60 -> 45669 | Q13: =+N13/2 -> 800000 | R13: =+H13-30 -> 45699 | S13: =+Q13 -> 800000 | AF13: =U13+X13+AA13+AD13 -> 0 | AG13: =+N13-U13-X13-AA13-AD13 -> 1600000 | AH13: =CONCATENATE(IF(AI13<0,IF(AI13>-30,IF(AG13>0,"T",""),""),IF(AI13>0,IF(AG13>0,"DEUDA",""),""))) | AI13: ='Pesca Nacional'!$AP$3-H13 -> -45729
A14: 11 | B14: Grupo Andes otoño | F14: =I14-H14 -> 4 | H14: 45729 | I14: 45733 | J14: =IF(F14=3,(1225000))+IF(F14=4,(1600000))+IF(F14=5,(1975000))+IF(F14=6,(2350000))+IF(F14=7,(2725000)) -> 1600000 | L14: =J14*K14 -> 0 | N14: =J14-L14+M14 -> 1600000 | O14: =N14/1.19 -> 1344537.8 | P14: =+H14-60 -> 45669 | Q14: =+N14/2 -> 800000 | R14: =+H14-30 -> 45699 | S14: =+Q14 -> 800000 | AF14: =U14+X14+AA14+AD14 -> 0 | AG14: =+N14-U14-X14-AA14-AD14 -> 1600000 | AH14: =CONCATENATE(IF(AI14<0,IF(AI14>-30,IF(AG14>0,"T",""),""),IF(AI14>0,IF(AG14>0,"DEUDA",""),""))) | AI14: ='Pesca Nacional'!$AP$3-H14 -> -45729
A15: 12 | B15: Grupo Andes otoño | F15: =I15-H15 -> 4 | H15: 45729 | I15: 45733 | J15: =IF(F15=3,(1225000))+IF(F15=4,(1600000))+IF(F15=5,(1975000))+IF(F15=6,(2350000))+IF(F15=7,(2725000)) -> 1600000 | L15: =J15*K15 -> 0 | N15: =J15-L15+M15 -> 1600000 | O15: =N15/1.19 -> 1344537.8 | P15: =+H15-60 -> 45669 | Q15: =+N15/2 -> 800000 | R15: =+H15-30 -> 45699 | S15: =+Q15 -> 800000 | AF15: =U15+X15+AA15+AD15 -> 0 | AG15: =+N15-U15-X15-AA15-AD15 -> 1600000 | AH15: =CONCATENATE(IF(AI15<0,IF(AI15>-30,IF(AG15>0,"T",""),""),IF(AI15>0,IF(AG15>0,"DEUDA",""),""))) | AI15: ='Pesca Nacional'!$AP$3-H15 -> -45729
... A22: 19 | B22: Grupo Central Anglers Otoño | F22: =I22-H22 -> 5 | H22: 45771 | I22: 45776 | J22: =IF(F22=3,(1225000))+IF(F22=4,(1600000))+IF(F22=5,(1975000))+IF(F22=6,(2350000))+IF(F22=7,(2725000)) -> 1975000 | L22: =J22*K22 -> 0 | N22: =J22-L22+M22 -> 1975000 | O22: =N22/1.19 -> 1659663.9 | P22: =+H22-60 -> 45711 | Q22: =+N22/2 -> 987500 | R22: =+H22-30 -> 45741 | S22: =+Q22 -> 987500 | AF22: =U22+X22+AA22+AD22 -> 0 | AG22: =+N22-U22-X22-AA22-AD22 -> 1975000 | AH22: =CONCATENATE(IF(AI22<0,IF(AI22>-30,IF(AG22>0,"T",""),""),IF(AI22>0,IF(AG22>0,"DEUDA",""),""))) | AI22: ='Pesca Nacional'!$AP$3-H22 -> -45771
A29: 26 | B29: Grupo Andes 2 | D29: Integrante 1 | F29: =I29-H29 -> 4 | G29: 45571 | H29: 45764 | I29: 45768 | J29: =IF(F29=3,(1225000))+IF(F29=4,(1600000))+IF(F29=5,(1975000))+IF(F29=6,(2350000))+IF(F29=7,(2725000)) -> 1600000 | K29: 0.2 | L29: =J29*K29 -> 320000 | N29: =J29-L29+M29 -> 1280000 | O29: =N29/1.19 -> 1075630.3 | P29: =+H29-60 -> 45704 | Q29: =+N29/2 -> 640000 | R29: =+H29-30 -> 45734 | S29: =+Q29 -> 640000 | AF29: =U29+X29+AA29+AD29 -> 0 | AG29: =+N29-U29-X29-AA29-AD29 -> 1280000 | AH29: =CONCATENATE(IF(AI29<0,IF(AI29>-30,IF(AG29>0,"T",""),""),IF(AI29>0,IF(AG29>0,"DEUDA",""),""))) | AI29: ='Pesca Nacional'!$AP$3-H29 -> -45764
A30: 27 | B30: Grupo Andes 2 | D30: Integrante 2 | F30: =I30-H30 -> 4 | G30: 45571 | H30: 45764 | I30: 45768 | J30: =IF(F30=3,(1225000))+IF(F30=4,(1600000))+IF(F30=5,(1975000))+IF(F30=6,(2350000))+IF(F30=7,(2725000)) -> 1600000 | K30: 0.2 | L30: =J30*K30 -> 320000 | N30: =J30-L30+M30 -> 1280000 | O30: =N30/1.19 -> 1075630.3 | P30: =+H30-60 -> 45704 | Q30: =+N30/2 -> 640000 | R30: =+H30-30 -> 45734 | S30: =+Q30 -> 640000 | AF30: =U30+X30+AA30+AD30 -> 0 | AG30: =+N30-U30-X30-AA30-AD30 -> 1280000 | AH30: =CONCATENATE(IF(AI30<0,IF(AI30>-30,IF(AG30>0,"T",""),""),IF(AI30>0,IF(AG30>0,"DEUDA",""),""))) | AI30: ='Pesca Nacional'!$AP$3-H30 -> -45764
A31: 28 | B31: Grupo Andes 2 | D31: Integrante 3 | F31: =I31-H31 -> 4 | G31: 45571 | H31: 45764 | I31: 45768 | J31: =IF(F31=3,(1225000))+IF(F31=4,(1600000))+IF(F31=5,(1975000))+IF(F31=6,(2350000))+IF(F31=7,(2725000)) -> 1600000 | K31: 0.2 | L31: =J31*K31 -> 320000 | N31: =J31-L31+M31 -> 1280000 | O31: =N31/1.19 -> 1075630.3 | P31: =+H31-60 -> 45704 | Q31: =+N31/2 -> 640000 | R31: =+H31-30 -> 45734 | S31: =+Q31 -> 640000 | AF31: =U31+X31+AA31+AD31 -> 0 | AG31: =+N31-U31-X31-AA31-AD31 -> 1280000 | AH31: =CONCATENATE(IF(AI31<0,IF(AI31>-30,IF(AG31>0,"T",""),""),IF(AI31>0,IF(AG31>0,"DEUDA",""),""))) | AI31: ='Pesca Nacional'!$AP$3-H31 -> -45764

Sheet Comparativo Pesca Nac
D6: TEMPORADA ACTUAL 25-26
D7: octubre | E7: noviembre | F7: diciembre | G7: enero | H7: febrero | I7: marzo | J7: abril | K7: mayo | L7: acumulado
C8: reservas | J8: 0 | K8: 0 | L8: =SUM(D8:K8) -> 0
C9: cañas | J9: 0 | K9: 0 | L9: =SUM(D9:K9) -> 0
C10: noches | J10: 0 | K10: 0 | L10: =SUM(D10:K10) -> 0
C11: monto | L11: =SUM(D11:K11) -> 0
D13: TEMPORADA ANTERIOR 24-25
D14: octubre | E14: noviembre | F14: diciembre | G14: enero | H14: febrero | I14: marzo | J14: abril | K14: mayo | L14: acumulado
C15: reservas | D15: 8 | E15: 7 | F15: 4 | G15: 1 | H15: 1 | I15: 1 | J15: 0 | K15: 0 | L15: =SUM(D15:K15) -> 22
C16: cañas | D16: 26 | E16: 27 | F16: 13 | G16: 2 | H16: 14 | I16: 17 | J16: 0 | K16: 0 | L16: =SUM(D16:K16) -> 99
C17: noches | D17: 129 | E17: 120 | F17: 57 | G17: 12 | H17: 98 | I17: 98 | J17: 0 | K17: 0 | L17: =SUM(D17:K17) -> 514
C18: monto | D18: 36373950 | E18: 37079832 | F18: 17813025 | G18: 3949500 | I18: 21428571 | L18: =SUM(D18:K18) -> 116644878
D20: TEMPORADA ANTERIOR 23-24
D21: octubre | E21: noviembre | F21: diciembre | G21: enero | H21: febrero | I21: abril | J21: mayo | L21: acumulado
C22: reservas | D22: 10 | E22: 12 | F22: 7 | G22: 3 | H22: 5 | I22: 10 | J22: 0
C23: cañas | D23: 30 | E23: 42 | F23: 23 | G23: 8 | H23: 15 | I23: 22 | J23: 0
C24: noches
C25: monto | D25: =45988888/1.19 -> 38646124 | E25: =53475849/1.19 -> 44937688 | F25: =34481152/1.19 -> 28975758 | G25: =14900000/1.19 -> 12521008 | H25: =21496800/1.19 -> 18064538 | I25: =27095955/1.19 -> 22769710
C26: reservas a la fecha

Sheet Pesca Extranjero
B1: CLIENTES NACIONALES | Q1: Calendario de Pago ($)
B2: Reserva | C2: Cliente | G2: Programa | I2: Fecha | J2: Fecha Ejecucion | L2: Tarifa Programa (S/I) | Q2: Abono Reserva (T-60/50%) | S2: Saldo Precio (T-30/50%) | U2: Pago 1 Real | X2: Pago 2 Real | AA2: Pago 3 Real | AD2: Pago 4 Real | AG2: Pagado a la | AH2: Saldo
B3: Numero | C3: Grupo | D3: Codigo Cloudbeds | E3: nombre | F3: RUT | G3: noches | I3: reserva | J3: Check In | K3: Check Out | L3: Lista | M3: Comision o Descuento | N3: Monto $Descuento | O3: Real | P3: Liquido | Q3: Fecha | R3: Monto | S3: Fecha | T3: Monto | U3: Fecha | V3: Monto | W3: Medio de pago | X3: Fecha | Y3: Monto | Z3: Medio de pago | AA3: Fecha | AB3: Monto | AC3: Medio de pago | AD3: Fecha | AE3: Monto | AF3: Medio de pago | AG3: Fecha | AH3: Adeudao
B4: 1 | C4: Grupo Orvis Hosted trip George Layton | E4: George Layton | G4: =K4-J4 -> 7 | H4: =G4*10 -> 70 | J4: 46032 | K4: 46039 | L4: =IF(G4=3,(3150))+IF(G4=4,(4050))+IF(G4=5,(4950))+IF(G4=6,(5850))+IF(G4=7,(6750)) -> 6750 | M4: 1 | N4: =L4*M4 -> 6750 | O4: =L4-N4 -> 0 | P4: - | Q4: =+J4-60 -> 45972 | R4: =+O4/2 -> 0 | S4: =+J4-30 -> 46002 | T4: =+R4 -> 0 | AG4: =V4+Y4+AB4+AE4 -> 0 | AH4: =AG4-O4 -> 0
B5: 2 | C5: Grupo Orvis Hosted trip George Layton | E5: Integrante 2 | G5: =K5-J5 -> 7 | J5: 46032 | K5: 46039 | L5: =IF(G5=3,(3150))+IF(G5=4,(4050))+IF(G5=5,(4950))+IF(G5=6,(5850))+IF(G5=7,(6750)) -> 6750 | M5: 0.2 | N5: =L5*M5 -> 1350 | O5: =L5-N5-860 -> 4540 | P5: =O5 -> 4540 | Q5: =+J5-60 -> 45972 | R5: =+O5/2 -> 2270 | S5: =+J5-30 -> 46002 | T5: =+R5 -> 2270 | AG5: =V5+Y5+AB5+AE5 -> 0 | AH5: =AG5-O5 -> -4540
A6: Total cañas | B6: 3 | C6: Grupo Orvis Hosted trip George Layton | E6: Integrante 3 | G6: =K6-J6 -> 7 | J6: 46032 | K6: 46039 | L6: =IF(G6=3,(3150))+IF(G6=4,(4050))+IF(G6=5,(4950))+IF(G6=6,(5850))+IF(G6=7,(6750)) -> 6750 | M6: 0.2 | N6: =L6*M6 -> 1350 | O6: =L6-N6-860 -> 4540 | P6: =O6 -> 4540 | Q6: =+J6-60 -> 45972 | R6: =+O6/2 -> 2270 | S6: =+J6-30 -> 46002 | T6: =+R6 -> 2270 | AG6: =V6+Y6+AB6+AE6 -> 0 | AH6: =AG6-O6 -> -4540
A7: =COUNT(B4:B157) -> 23 | B7: 4 | C7: Grupo Orvis Hosted trip George Layton | E7: Integrante 4 | G7: =K7-J7 -> 7 | J7: 46032 | K7: 46039 | L7: =IF(G7=3,(3150))+IF(G7=4,(4050))+IF(G7=5,(4950))+IF(G7=6,(5850))+IF(G7=7,(6750)) -> 6750 | M7: 0.2 | N7: =L7*M7 -> 1350 | O7: =L7-N7-860 -> 4540 | P7: =O7 -> 4540 | Q7: =+J7-60 -> 45972 | R7: =+O7/2 -> 2270 | S7: =+J7-30 -> 46002 | T7: =+R7 -> 2270 | AG7: =V7+Y7+AB7+AE7 -> 0 | AH7: =AG7-O7 -> -4540
B8: 5 | C8: Grupo Orvis Hosted trip George Layton | E8: Integrante 5 | G8: =K8-J8 -> 7 | J8: 46032 | K8: 46039 | L8: =IF(G8=3,(3150))+IF(G8=4,(4050))+IF(G8=5,(4950))+IF(G8=6,(5850))+IF(G8=7,(6750)) -> 6750 | M8: 0.2 | N8: =L8*M8 -> 1350 | O8: =L8-N8-860 -> 4540 | P8: =O8 -> 4540 | Q8: =+J8-60 -> 45972 | R8: =+O8/2 -> 2270 | S8: =+J8-30 -> 46002 | T8: =+R8 -> 2270 | AG8: =V8+Y8+AB8+AE8 -> 0 | AH8: =AG8-O8 -> -4540
B9: 6 | C9: Grupo Orvis Hosted trip George Layton | E9: Integrante 6 | G9: =K9-J9 -> 7 | J9: 46032 | K9: 46039 | L9: =IF(G9=3,(3150))+IF(G9=4,(4050))+IF(G9=5,(4950))+IF(G9=6,(5850))+IF(G9=7,(6750)) -> 6750 | M9: 0.2 | N9: =L9*M9 -> 1350 | O9: =L9-N9-860 -> 4540 | P9: =O9 -> 4540 | Q9: =+J9-60 -> 45972 | R9: =+O9/2 -> 2270 | S9: =+J9-30 -> 46002 | T9: =+R9 -> 2270 | AG9: =V9+Y9+AB9+AE9 -> 0 | AH9: =AG9-O9 -> -4540
A10: Total noches pesca inter. | B10: 7 | C10: Grupo Orvis Hosted trip George Layton | E10: Integrante 7 | G10: =K10-J10 -> 7 | J10: 46032 | K10: 46039 | L10: =IF(G10=3,(3150))+IF(G10=4,(4050))+IF(G10=5,(4950))+IF(G10=6,(5850))+IF(G10=7,(6750)) -> 6750 | M10: 0.2 | N10: =L10*M10 -> 1350 | O10: =L10-N10-860 -> 4540 | P10: =O10 -> 4540 | Q10: =+J10-60 -> 45972 | R10: =+O10/2 -> 2270 | S10: =+J10-30 -> 46002 | T10: =+R10 -> 2270 | AG10: =V10+Y10+AB10+AE10 -> 0 | AH10: =AG10-O10 -> -4540
A11: =SUM(G4:G26) -> 135 | B11: 8 | C11: Grupo Orvis Hosted trip George Layton | E11: Integrante 8 | G11: =K11-J11 -> 7 | J11: 46032 | K11: 46039 | L11: =IF(G11=3,(3150))+IF(G11=4,(4050))+IF(G11=5,(4950))+IF(G11=6,(5850))+IF(G11=7,(6750)) -> 6750 | M11: 0.2 | N11: =L11*M11 -> 1350 | O11: =L11-N11-860 -> 4540 | P11: =O11 -> 4540 | Q11: =+J11-60 -> 45972 | R11: =+O11/2 -> 2270 | S11: =+J11-30 -> 46002 | T11: =+R11 -> 2270 | AG11: =V11+Y11+AB11+AE11 -> 0 | AH11: =AG11-O11 -> -4540
B12: 9 | C12: Grupo Orvis Hosted trip George Layton | E12: Integrante 9 | G12: =K12-J12 -> 9 | J12: 46032 | K12: 46041 | L12: 8325 | M12: 0.2 | N12: =L12*M12 -> 1665 | O12: =L12-N12 -> 6660 | P12: =O12 -> 6660 | Q12: =+J12-60 -> 45972 | R12: =+O12/2 -> 3330 | S12: =+J12-30 -> 46002 | T12: =+R12 -> 3330 | AG12: =V12+Y12+AB12+AE12 -> 0 | AH12: =AG12-O12 -> -6660
A13: Total noches PE temporada | B13: 10 | C13: Grupo Orvis Hosted trip George Layton | E13: Integrante 10 | G13: =K13-J13 -> 9 | J13: 46032 | K13: 46041 | L13: 8325 | M13: 0.2 | N13: =L13*M13 -> 1665 | O13: =L13-N13 -> 6660 | P13: =O13 -> 6660 | Q13: =+J13-60 -> 45972 | R13: =+O13/2 -> 3330 | S13: =+J13-30 -> 46002 | T13: =+R13 -> 3330 | AG13: =V13+Y13+AB13+AE13 -> 0 | AH13: =AG13-O13 -> -6660
A14: =G4+G12+G14+G17+G23 -> 31 | B14: 11 | C14: Grupo harvey Freed | E14: Integrante 1 | G14: =K14-J14 -> 7 | H14: =G14*3 -> 21 | J14: 04/12/2025 | K14: 11/12/2025 | L14: 5625 | N14: =L14*M14 -> 0 | O14: =L14-N14 -> 5625 | P14: =O14 -> 5625 | Q14: =+J14-60 -> 45935 | R14: =+O14/2 -> 2812.5 | S14: =+J14-30 -> 45965 | T14: =+R14 -> 2812.5 | AG14: =V14+Y14+AB14+AE14 -> 0 | AH14: =AG14-O14 -> -5625
B15: 12 | C15: Grupo harvey Freed | E15: Integrante 2 | G15: =K15-J15 -> 7 | J15: 04/12/2025 | K15: 11/12/2025 | L15: 5625 | N15: =L15*M15 -> 0 | O15: =L15-N15 -> 5625 | P15: =O15 -> 5625 | Q15: =+J15-60 -> 45935 | R15: =+O15/2 -> 2812.5 | S15: =+J15-30 -> 45965 | T15: =+R15 -> 2812.5 | AG15: =V15+Y15+AB15+AE15 -> 0 | AH15: =AG15-O15 -> -5625
A16: Total liquido | B16: 13 | C16: Grupo harvey Freed | E16: Integrante 3 | G16: =K16-J16 -> 7 | J16: 04/12/2025 | K16: 11/12/2025 | L16: 5625 | N16: =L16*M16 -> 0 | O16: =L16-N16 -> 5625 | P16: =O16 -> 5625 | Q16: =+J16-60 -> 45935 | R16: =+O16/2 -> 2812.5 | S16: =+J16-30 -> 45965 | T16: =+R16 -> 2812.5 | AG16: =V16+Y16+AB16+AE16 -> 0 | AH16: =AG16-O16 -> -5625
A17: =SUM(P5:P37) -> 93403 | B17: 14 | C17: Grupo Orvis Joe Mathia | E17: Integrante 1 | G17: =K17-J17 -> 4 | H17: =G17*6 -> 24 | J17: 23/02/2026 | K17: 27-02-2026 | L17: 4050 | M17: 0.2 | N17: =L17*M17 -> 810 | O17: =L17-N17 -> 3240 | P17: =O17 -> 3240
B18: 15 | C18: Grupo Orvis Joe Mathia | E18: Integrante 2 | G18: =K18-J18 -> 4 | J18: 23/02/2026 | K18: 27-02-2026 | L18: 4050 | M18: 0.2 | N18: =L18*M18 -> 810 | O18: =L18-N18 -> 3240 | P18: =O18 -> 3240
B19: 16 | C19: Grupo Orvis Joe Mathia | E19: Integrante 3 | G19: =K19-J19 -> 4 | J19: 23/02/2026 | K19: 27-02-2026 | L19: 4050 | M19: 0.2 | N19: =L19*M19 -> 810 | O19: =L19-N19 -> 3240 | P19: =O19 -> 3240
B20: 17 | C20: Grupo Orvis Joe Mathia | E20: Integrante 4 | G20: =K20-J20 -> 4 | J20: 23/02/2026 | K20: 27-02-2026 | L20: 4050 | M20: 0.2 | N20: =L20*M20 -> 810 | O20: =L20-N20 -> 3240 | P20: =O20 -> 3240
B21: 18 | C21: Grupo Orvis Joe Mathia | E21: Integrante 5 | G21: =K21-J21 -> 4 | J21: 23/02/2026 | K21: 27-02-2026 | L21: 4050 | M21: 0.2 | N21: =L21*M21 -> 810 | O21: =L21-N21 -> 3240 | P21: =O21 -> 3240
B22: 19 | C22: Grupo Orvis Joe Mathia | E22: Integrante 6 | G22: =K22-J22 -> 4 | J22: 23/02/2026 | K22: 27-02-2026 | L22: 4050 | M22: 0.2 | N22: =L22*M22 -> 810 | O22: =L22-N22 -> 3240 | P22: =O22 -> 3240
B23: 20 | C23: Grupo 4 elements | E23: integrante 1 | G23: 4 | J23: 09-03-2026 | K23: 13-03-2026 | L23: 4050 | M23: 0.2 | N23: =L23*M23 -> 810 | O23: =L23-N23 -> 3240 | P23: =O23 -> 3240
B24: 21 | C24: Grupo 4 elements | E24: Integrante 2 | G24: 4 | J24: 09-03-2026 | K24: 13-03-2026 | L24: 4050 | M24: 0.2 | N24: =L24*M24 -> 810 | O24: =L24-N24 -> 3240 | P24: =O24 -> 3240
B25: 22 | C25: Grupo 4 elements | E25: Integrante 3 | G25: 4 | J25: 09-03-2026 | K25: 13-03-2026 | L25: 4050 | M25: 0.2 | N25: =L25*M25 -> 810 | O25: =L25-N25 -> 3240 | P25: =O25 -> 3240
B26: 23 | C26: Grupo 4 elements | E26: Integrante 4 | G26: 4 | J26: 09-03-2026 | K26: 13-03-2026 | L26: 2835 | M26: 0.2 | N26: =L26*M26 -> 567 | O26: =L26-N26 -> 2268 | P26: =O26 -> 2268

Sheet Comparativo Pesca Extranjero
D6: TEMPORADA ACTUAL
D7: octubre | E7: noviembre | F7: diciembre | G7: enero | H7: febrero | I7: abril | J7: mayo | K7: acumulado
C8: reservas
C9: cañas
C10: noches
C11: monto
D13: TEMPORADA ANTERIOR
D14: octubre | E14: noviembre | F14: diciembre | G14: enero | H14: febrero | I14: abril | J14: mayo | K14: acumulado
C15: reservas
C16: cañas
C17: noches
C18: monto
C19: reservas a la fecha

Sheet Pesca por el Dia
B1: CLIENTES NACIONALES
B2: Reserva | C2: Cliente | F2: Half o | G2: Fecha | H2: Fecha | I2: Tarifa Programa (S/I) | N2: Pago 1 Real | Q2: Pago 2 Real | T2: Pago 3 Real | W2: Pago 4 Real | Z2: Saldo
B3: Numero | C3: Grupo | D3: nombre | E3: RUT | F3: Full day | G3: reserva | H3: Ejecucion | I3: Lista | J3: Comision o Descuento | K3: Monto $Descuento | L3: Bruto | M3: Liquido | N3: Fecha | O3: Monto | P3: Medio de pago | Q3: Fecha | R3: Monto | S3: Medio de pago | T3: Fecha | U3: Monto | V3: Medio de pago | W3: Fecha | X3: Monto | Y3: Medio de pago | Z3: Adeudao
B4: 1 | C4: GRUPO RUSH | D4: Borde baker | F4: 1 | H4: 46091 | I4: =IF(F4=1,(500000))+IF(F4=0.5,(350000)) -> 500000 | J4: 0.2 | K4: =I4*J4 -> 100000 | L4: =I4-K4 -> 400000 | M4: =L4/1.19 -> 336134.45
B5: 2 | C5: GRUPO EXPLORA | F5: 1 | G5: 45889 | H5: 46019 | I5: =IF(F5=1,(500000))+IF(F5=0.5,(350000)) -> 500000 | J5: 0.2 | K5: =I5*J5 -> 100000 | L5: =I5-K5 -> 400000 | M5: =L5/1.19 -> 336134.45
A6: Total pescas por dia | B6: 3 | C6: GRUPO EXPLORA | F6: 1 | G6: 45889 | H6: 46020 | I6: =IF(F6=1,(500000))+IF(F6=0.5,(350000)) -> 500000 | J6: 0.2 | K6: =I6*J6 -> 100000 | L6: =I6-K6 -> 400000 | M6: =L6/1.19 -> 336134.45
A7: =COUNT(B4:B87) -> 55 | B7: 4 | C7: GRUPO EXPLORA | F7: 1 | G7: 45889 | H7: 46020 | I7: =IF(F7=1,(500000))+IF(F7=0.5,(350000)) -> 500000 | J7: 0.2 | K7: =I7*J7 -> 100000 | L7: =I7-K7 -> 400000 | M7: =L7/1.19 -> 336134.45
B8: 5 | C8: GRUPO EXPLORA | F8: 1 | G8: 45889 | H8: 46020 | I8: =IF(F8=1,(500000))+IF(F8=0.5,(350000)) -> 500000 | J8: 0.2 | K8: =I8*J8 -> 100000 | L8: =I8-K8 -> 400000 | M8: =L8/1.19 -> 336134.45
B9: 6 | C9: GRUPO EXPLORA | F9: 1 | G9: 45890 | H9: 46021 | I9: =IF(F9=1,(500000))+IF(F9=0.5,(350000)) -> 500000 | J9: 0.2 | K9: =I9*J9 -> 100000 | L9: =I9-K9 -> 400000 | M9: =L9/1.19 -> 336134.45
A10: Total bruto nac. | B10: 7 | C10: GRUPO EXPLORA | F10: 1 | G10: 45891 | H10: 46021 | I10: =IF(F10=1,(500000))+IF(F10=0.5,(350000)) -> 500000 | J10: 0.2 | K10: =I10*J10 -> 100000 | L10: =I10-K10 -> 400000 | M10: =L10/1.19 -> 336134.45
A11: =SUM(L4:L77) -> 22090000 | B11: 8 | C11: GRUPO EXPLORA | F11: 1 | G11: 45892 | H11: 46021 | I11: =IF(F11=1,(500000))+IF(F11=0.5,(350000)) -> 500000 | J11: 0.2 | K11: =I11*J11 -> 100000 | L11: =I11-K11 -> 400000 | M11: =L11/1.19 -> 336134.45
B12: 9 | C12: GRUPO EXPLORA | F12: 1 | G12: 45893 | H12: 46022 | I12: =IF(F12=1,(500000))+IF(F12=0.5,(350000)) -> 500000 | J12: 0.2 | K12: =I12*J12 -> 100000 | L12: =I12-K12 -> 400000 | M12: =L12/1.19 -> 336134.45
B13: 10 | C13: GRUPO EXPLORA | F13: 1 | G13: 45894 | H13: 46022 | I13: =IF(F13=1,(500000))+IF(F13=0.5,(350000)) -> 500000 | J13: 0.2 | K13: =I13*J13 -> 100000 | L13: =I13-K13 -> 400000 | M13: =L13/1.19 -> 336134.45
A14: Total liquido nac. | B14: 11 | C14: GRUPO EXPLORA | F14: 1 | G14: 45895 | H14: 46022 | I14: =IF(F14=1,(500000))+IF(F14=0.5,(350000)) -> 500000 | J14: 0.2 | K14: =I14*J14 -> 100000 | L14: =I14-K14 -> 400000 | M14: =L14/1.19 -> 336134.45
A15: =SUM(M4:M77) -> 18563025 | B15: 12 | C15: GRUPO HALLE YUNGMEYER | F15: 1 | G15: 45926 | H15: 46051 | I15: =IF(F15=1,(500000))+IF(F15=0.5,(350000)) -> 500000 | K15: =I15*J15 -> 0 | L15: =I15-K15 -> 500000 | M15: =L15/1.19 -> 420168.07
B16: 13 | C16: GRUPO HALLE YUNGMEYER | F16: 1 | G16: 45926 | H16: 46051 | I16: =IF(F16=1,(500000))+IF(F16=0.5,(350000)) -> 500000 | K16: =I16*J16 -> 0 | L16: =I5-K16 -> 500000 | M16: =L16/1.19 -> 420168.07
B17: 14 | C17: GRUPO HALLE YUNGMEYER | F17: 1 | G17: 45926 | H17: 46051 | I17: =IF(F17=1,(500000))+IF(F17=0.5,(350000)) -> 500000 | K17: =I17*J17 -> 0 | L17: =I17-K17 -> 500000 | M17: =L17/1.19 -> 420168.07
B18: 15 | C18: GRUPO OPAZO | F18: 1 | G18: 45960 | H18: 45995 | I18: 350000 | K18: =I18*J18 -> 0 | L18: =I18-K18 -> 350000 | M18: =L18/1.19 -> 294117.65
B19: 16 | C19: GRUPO OPAZO | F19: 1 | G19: 45960 | H19: 45995 | I19: 350000 | K19: =I19*J19 -> 0 | L19: =I19-K19 -> 350000 | M19: =L19/1.19 -> 294117.65
B20: 17 | C20: GRUPO EXPLORA | F20: 1 | H20: 46011 | I20: 500000 | J20: 0.2 | K20: =I20*J20 -> 100000 | L20: =I20-K20 -> 400000 | M20: =L20/1.19 -> 336134.45
B21: 18 | C21: GRUPO GREG VERNON | F21: 1 | H21: 46030 | I21: 500000 | K21: =I21*J21 -> 0 | L21: =I21-K21 -> 500000 | M21: =L21/1.19 -> 420168.07
B22: 19 | C22: GRUPO GREG VERNON | F22: 1 | H22: 46030 | I22: 500000 | K22: =I22*J22 -> 0 | L22: =I22-K22 -> 500000 | M22: =L22/1.19 -> 420168.07
B23: 20 | C23: GRUPO EXLORA | F23: 1 | G23: 46009 | H23: 46010 | I23: 500000 | J23: 0.2 | K23: =I23*J23 -> 100000 | L23: =I23-K23 -> 400000 | M23: =L23/1.19 -> 336134.45
B24: 21 | C24: GRUPO EXLORA | F24: 1 | G24: 46009 | H24: 46010 | I24: 500000 | J24: 0.2 | K24: =I24*J24 -> 100000 | L24: =I24-K24 -> 400000 | M24: =L24/1.19 -> 336134.45
B25: 22 | C25: CONSUELO GAMOND | H25: 46050 | I25: 500000 | K25: =I25*J25 -> 0 | L25: =I25-K25 -> 500000 | M25: =L25/1.19 -> 420168.07
B26: 23 | C26: CONSUELO GAMOND | H26: 46050 | I26: 500000 | K26: =I26*J26 -> 0 | L26: =I26-K26 -> 500000 | M26: =L26/1.19 -> 420168.07
B27: 24 | C27: CONSUELO GAMOND | H27: 46049 | I27: 350000 | K27: 0 | L27: =I27-K27 -> 350000 | M27: =L27/1.19 -> 294117.65
B28: 25 | C28: CONSUELO GAMOND | H28: 46049 | I28: 350000 | K28: 0 | L28: =I28-K28 -> 350000 | M28: =L28/1.19 -> 294117.65
B29: 26 | C29: GONZALO COBARRUBIAS | F29: 1 | G29: 46007 | H29: 45707 | I29: 500000 | K29: =I29*J29 -> 0 | L29: =I29-K29 -> 500000 | M29: =L29/1.19 -> 420168.07
B30: 27 | C30: GONZALO COBARRUBIAS | F30: 1 | G30: 46007 | H30: 45707 | I30: 500000 | K30: =I30*J30 -> 0 | L30: =I30-K30 -> 500000 | M30: =L30/1.19 -> 420168.07
B31: 28 | C31: GONZALO COBARRUBIAS | F31: 1 | G31: 46007 | H31: 45707 | I31: 500000 | K31: =I31*J31 -> 0 | L31: =I31-K31 -> 500000 | M31: =L31/1.19 -> 420168.07
B32: 29 | C32: PESCA SUDAFRICA | F32: 45689 | H32: 46017 | I32: 350000 | K32: =I32*J32 -> 0 | L32: =I32-K32 -> 350000 | M32: =L32/1.19 -> 294117.65
B33: 30 | C33: GARRETT | F33: 45689 | H33: 46017 | I33: 350000 | K33: =I33*J33 -> 0 | L33: =I33-K33 -> 350000 | M33: =L33/1.19 -> 294117.65
B34: 31 | C34: GARRETT | F34: 45689 | H34: 46018 | I34: 350000 | K34: =I34*J34 -> 0 | L34: =I34-K34 -> 350000 | M34: =L34/1.19 -> 294117.65
B35: 32 | C35: NN | F35: 1 | I35: 350000 | K35: =I35*J35 -> 0 | L35: =I35-K35 -> 350000 | M35: =L35/1.19 -> 294117.65
B36: 33 | C36: MEREDITH Y NED | F36: 46054 | H36: 46069 | I36: 350000 | K36: =I36*J36 -> 0 | L36: =I36-K36 -> 350000 | M36: =L36/1.19 -> 294117.65
B37: 34 | C37: MAURICIO VALENZUELA | F37: 1 | G37: 46027 | H37: 46052 | I37: 500000 | J37: 0.2 | K37: =I37*J37 -> 100000 | L37: =I37-K37 -> 400000 | M37: =L37/1.19 -> 336134.45
B38: 35 | C38: EXPLORA | F38: 1 | G38: 45673 | H38: 45675 | I38: 500000 | J38: 0.2 | K38: =I38*J38 -> 100000 | L38: =I38-K38 -> 400000 | M38: =L38/1.19 -> 336134.45
B39: 36 | C39: EXPLORA | F39: 46054 | G39: 46051 | H39: 46054 | I39: 350000 | J39: 0.2 | K39: =I39*J39 -> 70000 | L39: =I39-K39 -> 280000 | M39: =L39/1.19 -> 235294.12
B40: 37 | C40: GRIMUR | F40: 1 | H40: 46086 | I40: 350000 | J40: 0 | K40: =I40*J40 -> 0 | L40: =I40-K40 -> 350000 | M40: =L40/1.19 -> 294117.65
...

Sheet Guias disponibles
A1: GUIAS DISPONIBLES | C1: DIA | D1: ENERO | E1: FEBRERO | F1: MARZO | G1: ABRIL | H1: MAYO
A2: PARA PESCA POR DIA | C2: 1
C3: 2
A4: Leyenda | C4: 3
B5: Dia agendado | C5: 4
B6: Si se requiere as disponibilidad | C6: 5
B7: consultar RBP | C7: 6
A8: #Guia disponible | B8: Nombre de Guia | C8: 7
A9: () | B9: Origen clientes | C9: 8
A10: - | B10: Sin disponibilidad | C10: 9
A11: 1 | B11: full day | C11: 10
A12: 45689 | B12: half day | C12: 11
C13: 12
C14: 13
C15: 14
C16: 15
C17: 16
C18: 17
C19: 18
C20: 19
C21: 20
C22: 21
C23: 22
C24: 23
... C32: 31

Sheet GLOBAL PESCA
A1: GLOBAL
A2: ESTADISTICAS PESCA
A3: NACIONAL | B3: Total cañas nac. | D3: Total noches pesca nac. | F3: Total noches PN temporada | H3: Total bruto nac. | J3: Total liquido nac.
B4: ='Pesca Nacional'!A7 -> 129 | D4: ='Pesca Nacional'!A11 -> 546 | F4: ='Pesca Nacional'!A15 -> 139 | H4: ='Pesca Nacional'!A19 -> 208347000 | J4: ='Pesca Nacional'!A23 -> 1.7508151e+08
A6: EXTRANJEROS | B6: Total cañas extr. | D6: Total noches pesca extr. | F6: Total noches PE temporada | H6: Total bruto extr. USD | J6: Total liquido extr. USD | L6: * USD A | M6: 900
B7: ='Pesca Extranjero'!A7 -> 23 | D7: ='Pesca Extranjero'!A11 -> 135 | F7: ='Pesca Extranjero'!A14 -> 31 | H7: ='Pesca Extranjero'!A17 -> 93403 | J7: =H7*900 -> 84062700
A9: PESCA POR DIA | B9: Total pescas por dia | H9: Total bruto pesca x dia | J9: Total liquido pesca x dia
B10: =COUNT('Pesca por el Dia'!B4:B55) -> 52 | H10: ='Pesca por el Dia'!A11 -> 22090000 | J10: ='Pesca por el Dia'!A15 -> 18563025
A12: TOTALES GLOBALES | B12: Total cañas | D12: Total noches pesca | F12: Total noches pesca temporada | H12: Total bruto | J12: Total liquido
B13: =B4+B7+B10 -> 204 | D13: =D4+D7 -> 681 | F13: =F4+F7 -> 170 | H13: =H4+(H7*950)+H10 -> 319169850 | J13: =J4+J7+J10 -> 2.7770724e+08

Sheet Listado clientes
B1: 1 | C1: Grupo Santolaya | E1: Gonzalo Santolaya | G1: 1 | H1: Grupo Orvis Hosted trip George Layton | J1: George Layton
B2: 2 | C2: Grupo Santolaya | E2: Polola Santolaya | G2: 2 | H2: Grupo Orvis Hosted trip George Layton | J2: Integrante 2
B3: 3 | C3: Grupo Cuñado Solminihac | E3: Marcelo Flores | G3: 3 | H3: Grupo Orvis Hosted trip George Layton | J3: Integrante 3
B4: 4 | C4: Grupo Cuñado Solminiach | E4: Claudia Solminiach | G4: 4 | H4: Grupo Orvis Hosted trip George Layton | J4: Integrante 4
B5: 5 | C5: Grupo Cuñado Solminiach | E5: Integrante 3 | G5: 5 | H5: Grupo Orvis Hosted trip George Layton | J5: Integrante 5
B6: 6 | C6: Grupo Cuñado Solminiach | E6: Integrante 4 | G6: 6 | H6: Grupo Orvis Hosted trip George Layton | J6: Integrante 6
B7: 7 | C7: Grupo Barroso | E7: Juan Pablo Barroso | G7: 7 | H7: Grupo Orvis Hosted trip George Layton | J7: Integrante 7
B8: 8 | C8: Grupo Barroso | E8: Alan Bey | G8: 8 | H8: Grupo Orvis Hosted trip George Layton | J8: Integrante 8
B9: 9 | C9: Grupo Barroso | E9: Pablo Moccocian | G9: 19 | H9: Grupo Nak Nek | J9: Jim Johnson
B10: 10 | C10: Grupo Barroso | E10: Mauricio Alamos | G10: 20 | H10: Grupo Nak Nek | J10: Phyllis Johnson
B11: 11 | C11: Grupo Quezada | E11: Ruben Quezada | G11: 21 | H11: Grupo Nak Nek | J11: Integrante 1
B12: 12 | C12: Grupo Quezada | E12: Piero Bolognesi | G12: 22 | H12: Grupo Nak Nek | J12: Integrante 2
... B14: 14 | C14: Grupo Quezada | E14: Eduardo Torrejon | G14: 24 | H14: Grupo Nak Nek | J14: Integrante 4
B15: 15 | C15: Grupo Quezada | E15: Miguel Nazar | H15: Grupo Nak Nek | J15: Integrante 5
B16: 16 | C16: Grupo Andes 1 | E16: Gustavo Errazuriz | G16: 25 | H16: Grupo Francois | J16: Integrante 1
B17: 17 | C17: Grupo Andes 2 | E17: Carlos Allimant | G17: 26 | H17: Grupo Francois | J17: Integrante 2
B18: 18 | C18: Grupo Andes 2 | E18: Marco Toledo | G18: 27 | H18: Grupo Big Sky Anglers 3 | J18: Integrante 1
B19: 19 | C19: Grupo Andes 2 | E19: Gozalo Tejero | G19: 28 | H19: Grupo Big Sky Anglers 3 | J19: Integrante 2
B20: 20 | C20: Grupo Andes 2 | E20: S. Rossi | G20: 29 | H20: Grupo Big Sky Anglers 3 | J20: Host
B21: 21 | C21: Grupo Tomas Icaza | E21: Tomas Icaza | G21: 30 | H21: Grupo Big Sky Anglers 3 | J21: Host
B22: 22 | C22: Grupo Tomas Icaza | E22: Lucas Nichols | G22: 31 | H22: Grupo White Rivers | J22: Steve Sonnamaker
B23: 23 | C23: Grupo Tomas Icaza | E23: Jorge Marimon | G23: 32 | H23: Grupo White Rivers | J23: Host
B24: 24 | C24: Grupo Tomas Icaza | E24: Intrgrante 4 | G24: 33 | H24: Grupo Mike Carl | J24: Mike Carl
B25: 25 | C25: Grupo Stipicic | E25: Carlos Stipicic | G25: 34 | H25: Grupo Mike Carl | J25: Bill Comai
B26: 26 | C26: Grupo Stipicic | E26: Amador Stipicic | G26: 35 | H26: Grupo Mike Carl | J26: Jim Bour
B27: 27 | C27: Grupo Stipicic | E27: Doug Ort | G27: 36 | H27: Grupo Mike Carl | J27: Integrante 4
... B41: 41 | C41: Grupo Contreras | E41: Hugo Rojas | G41: 51 | H41: Grupo Orvis Spink | J41: William Spink
B42: 42 | C42: Grupo Contreras | E42: Alejandro Kaulen
B43: 43 | C43: Grupo Irribarra | E43: Roberto Irribara
B44: 44 | C44: Grupo Irribarra | E44: Francisco Chacon
B45: 45 | C45: Grupo Gellona | E45: Jose Gellona
B46: 46 | C46: Grupo Gellona | E46: Jose Pablo Vergara
B47: 47 | C47: Grupo Gellona | E47: Jose Vergara
B48: 48 | C48: Grupo Gellona | E48: Pablo Gellona
B49: 49 | C49: Grupo Gellona | E49: Pablo Risso
B50: 50 | C50: Grupo Gellona | E50: Francisco Cervantes
B51: 51 | C51: Grupo Gellona | E51: Rodrigo Val
B52: 52 | C52: Grupo Gellona | E52: Javier Molinos
B53: 53 | C53: Grupo Joaquin Garcia | E53: Gian Carlos Rovengo
... B114: 116 | C114: Grupo Perez | E114: Matias Irrarazabal
...

Sheet Hoja1
B1: Nombre | C1: 1 Apellido | D1: 2 Apellido | E1: Nacionalidad | F1: Email | G1: Telefono | H1: Idioma | I1: Mercado
A2: Alan Bey | B2: Alan | C2: Bey
A3: Alejandro Kaulen | B3: Alejandro | C3: Kaulen
A4: Alex | B4: Alex
A5: Alvaro Contreras | B5: Alvaro | C5: Contreras
A6: Amador Stipicic | B6: Amador | C6: Stipicic
A7: Andres Dighero | B7: Andres | C7: Dighero
A8: Arturo Palma | B8: Arturo | C8: Palma
A9: Benjamin Garcia | B9: Benjamin | C9: Garcia
A10: Benjamin Undurraga | B10: Benjamin | C10: Undurraga
A11: Camara man
A12: Carlos Allimant | B12: Carlos | C12: Allimant
A13: Carlos Cornejo | B13: Carlos | C13: Cornejo
A14: Carlos Stipicic | B14: Carlos | C14: Stipicic
A15: Cesar Gavilan | B15: Cesar | C15: Gavilan
A16: Claudia Solminiach | B16: Claudia | C16: Solminiach
A17: Claudio Araya | B17: Claudio | C17: Araya
A18: Cosmelli
A19: Diego Julio | B19: Diego
A20: Doug Ort | B20: Doug
A21: Eduardo Torrejon | B21: Eduardo
A22: Eduardo Von Krestshmann | B22: Eduardo
A23: Fco Quintanilla | B23: Francisco
A24: Francisco Cervantes | B24: Francisco
A25: Francisco Chacon | B25: Francisco
A26: Gian Carlos Rovengo | B26: Giancarlos
A27: Gino Defilippi | B27: Gino
A28: Gonzalo Ausin | B28: Gonzalo
A29: Gonzalo Garcia | B29: Gonzalo
A30: Gonzalo Iturriaga | B30: Gonzalo
... A36: Gustavo Errazuriz | B36: Gustavo
A37: Hermana Alejandro
A38: Hijo Cabello
A39: Hijo Doug
A40: Hijo Gavilan
A41: Hijo Santolaya
A42: Hijo Stitchkin
A43: Hugo Labrin | B43: Hugo
A44: Hugo Rojas | B44: Hugo
A45: Humberto Dighero | B45: Humberto
...
