Workbook

Sheet RESERVAS
B4: Información de Estadía
B5: Fecha de reserva
B6: Check-In
B7: N˚ Noches
B8: Check-Out | D8: =IF(D7="","",(D6+D7))
B10: Información de Grupo
B11: Nacional/Extranjero
B12: Información Personal | H12: Información del Programa
B13: Pasajero | C13: ¿Primera vez que viene? | D13: Nombre completo | E13: Mail | F13: Número de contacto | G13: Género | H13: Base | I13: Check-In | J13: N˚ Noches | K13: Check-Out | L13: Tipo | M13: Observaciones
A14: Si | B14: Encargado | J14: =+IF(I14="","",D7) | K14: =+IF(I14="","",I14+J14)
A15: Si | B15: N˚ 2 | J15: =+IF(I15="","",D8) | K15: =+IF(I15="","",I15+J15)
A16: Si | B16: N˚ 3 | J16: =+IF(I16="","",D9) | K16: =+IF(I16="","",I16+J16)
A17: Si | B17: N˚ 4 | J17: =+IF(I17="","",#REF!) | K17: =+IF(I17="","",I17+J17)
A18: Si | B18: N˚ 5 | J18: =+IF(I18="","",#REF!) | K18: =+IF(I18="","",I18+J18)
A19: Si | B19: N˚ 6 | J19: =+IF(I19="","",#REF!) | K19: =+IF(I19="","",I19+J19)
A20: Si | B20: N˚ 7 | J20: =+IF(I20="","",#REF!) | K20: =+IF(I20="","",I20+J20)
A21: Si | B21: N˚ 8 | J21: =+IF(I21="","",#REF!) | K21: =+IF(I21="","",I21+J21)
A22: Si | B22: N˚ 9 | J22: =+IF(I22="","",#REF!) | K22: =+IF(I22="","",I22+J22)
A23: Si | B23: N˚ 10 | J23: =+IF(I23="","",#REF!) | K23: =+IF(I23="","",I23+J23)
A24: No | B24: Encargado | J24: =+IF(I24="","",#REF!) | K24: =+IF(I24="","",I24+J24)
A25: No | B25: N˚ 2 | J25: =+IF(I25="","",#REF!) | K25: =+IF(I25="","",I25+J25)
A26: No | B26: N˚ 3 | J26: =+IF(I26="","",#REF!) | K26: =+IF(I26="","",I26+J26)
A27: No | B27: N˚ 4 | J27: =+IF(I27="","",#REF!) | K27: =+IF(I27="","",I27+J27)
A28: No | B28: N˚ 5 | J28: =+IF(I28="","",#REF!) | K28: =+IF(I28="","",I28+J28)
... A30: No | B30: N˚ 7 | J30: =+IF(I30="","",#REF!) | K30: =+IF(I30="","",I30+J30)
A31: No | B31: N˚ 8 | J31: =+IF(I31="","",D10) | K31: =+IF(I31="","",I31+J31)
A32: No | B32: N˚ 9 | J32: =+IF(I32="","",D12) | K32: =+IF(I32="","",I32+J32)
A33: No | B33: N˚ 10 | J33: =+IF(I33="","",D13) | K33: =+IF(I33="","",I33+J33)

Sheet BBDD
A1: Código interno | B1: Información Pasajero | I1: Información Reserva | M1: Información Pricing | Q1: Seguimiento Cobranza Reserva | AA1: Seguimiento Cobranza Saldo | AI1: Observaciones
B2: Grupo | C2: Pasajero | D2: Nombre Completo | E2: Mail | F2: Número de Contacto | G2: Género | H2: Tipo | I2: Fecha de Reserva | J2: Check-In | K2: N° Noches | L2: Check-Out | M2: Base | N2: Grupo Extranjero/Nacional | O2: Valor Bruto Programa | P2: Descuento | Q2: Reserva - 105 Días | R2: Reserva - 90 Días | S2: Reserva - 75 Días | T2: Reserva - 60 Días | U2: Reserva - 45 Días | V2: Reserva - 30 Días | W2: Reserva - Llamar | X2: Reserva - Fecha de Pago | Y2: Reserva - Monto Bruto | Z2: Reserva - Medio de Pago | AA2: Saldo - 45 Días | AB2: Saldo - 30 Días | AC2: Saldo - 15 Días | AD2: Saldo - 7 Días | AE2: Saldo - Llamar | AF2: Saldo - Fecha de Pago | AG2: Saldo - Monto Bruto | AH2: Saldo - Medio de Pago
A3: =+IF(D3="","",CONCATENATE("GBL 00",Mantenedor!E2)) | L3: =IF(K3="","",(J3+K3)) | N3: =IF($K3="","",IF($K3=1,CONCATENATE("Base ",$M3," ",$K3," noche"),CONCATENATE("Base ",$M3," ",$K3," noches"))) | O3: =IFERROR(IF(M3="Host","0",VLOOKUP($N3,Pricing!$D$2:$E$43,2,FALSE)),"")
A4: =+IF(D4="","",CONCATENATE("GBL 00",Mantenedor!E3)) | L4: =IF(K4="","",(J4+K4)) | N4: =IF($K4="","",IF($K4=1,CONCATENATE("Base ",$M4," ",$K4," noche"),CONCATENATE("Base ",$M4," ",$K4," noches"))) | O4: =IFERROR((VLOOKUP($N4,Pricing!$D$2:$E$43,2,FALSE)),"")
A5: =+IF(D5="","",CONCATENATE("GBL 00",Mantenedor!E4)) | L5: =IF(K5="","",(J5+K5)) | N5: =IF($K5="","",IF($K5=1,CONCATENATE("Base ",$M5," ",$K5," noche"),CONCATENATE("Base ",$M5," ",$K5," noches"))) | O5: =IFERROR((VLOOKUP($N5,Pricing!$D$2:$E$43,2,FALSE)),"")
A6: =+IF(D6="","",CONCATENATE("GBL 00",Mantenedor!E5)) | L6: =IF(K6="","",(J6+K6)) | N6: =IF($K6="","",IF($K6=1,CONCATENATE("Base ",$M6," ",$K6," noche"),CONCATENATE("Base ",$M6," ",$K6," noches"))) | O6: =IFERROR((VLOOKUP($N6,Pricing!$D$2:$E$43,2,FALSE)),"")
A7: =+IF(D7="","",CONCATENATE("GBL 00",Mantenedor!E6)) | L7: =IF(K7="","",(J7+K7)) | N7: =IF($K7="","",IF($K7=1,CONCATENATE("Base ",$M7," ",$K7," noche"),CONCATENATE("Base ",$M7," ",$K7," noches"))) | O7: =IFERROR((VLOOKUP($N7,Pricing!$D$2:$E$43,2,FALSE)),"")
A8: =+IF(D8="","",CONCATENATE("GBL 00",Mantenedor!E7)) | L8: =IF(K8="","",(J8+K8)) | N8: =IF($K8="","",IF($K8=1,CONCATENATE("Base ",$M8," ",$K8," noche"),CONCATENATE("Base ",$M8," ",$K8," noches"))) | O8: =IFERROR((VLOOKUP($N8,Pricing!$D$2:$E$43,2,FALSE)),"")
A9: =+IF(D9="","",CONCATENATE("GBL 00",Mantenedor!E8)) | L9: =IF(K9="","",(J9+K9)) | N9: =IF($K9="","",IF($K9=1,CONCATENATE("Base ",$M9," ",$K9," noche"),CONCATENATE("Base ",$M9," ",$K9," noches"))) | O9: =IFERROR((VLOOKUP($N9,Pricing!$D$2:$E$43,2,FALSE)),"")
A10: =+IF(D10="","",CONCATENATE("GBL 00",Mantenedor!E9)) | L10: =IF(K10="","",(J10+K10)) | N10: =IF($K10="","",IF($K10=1,CONCATENATE("Base ",$M10," ",$K10," noche"),CONCATENATE("Base ",$M10," ",$K10," noches"))) | O10: =IFERROR((VLOOKUP($N10,Pricing!$D$2:$E$43,2,FALSE)),"")
A11: =+IF(D11="","",CONCATENATE("GBL 00",Mantenedor!E10)) | L11: =IF(K11="","",(J11+K11)) | N11: =IF($K11="","",IF($K11=1,CONCATENATE("Base ",$M11," ",$K11," noche"),CONCATENATE("Base ",$M11," ",$K11," noches"))) | O11: =IFERROR((VLOOKUP($N11,Pricing!$D$2:$E$43,2,FALSE)),"")
A12: =+IF(D12="","",CONCATENATE("GBL 00",Mantenedor!E11)) | L12: =IF(K12="","",(J12+K12)) | N12: =IF($K12="","",IF($K12=1,CONCATENATE("Base ",$M12," ",$K12," noche"),CONCATENATE("Base ",$M12," ",$K12," noches"))) | O12: =IFERROR((VLOOKUP($N12,Pricing!$D$2:$E$43,2,FALSE)),"")
A13: =+IF(D13="","",CONCATENATE("GBL 00",Mantenedor!E12)) | L13: =IF(K13="","",(J13+K13)) | N13: =IF($K13="","",IF($K13=1,CONCATENATE("Base ",$M13," ",$K13," noche"),CONCATENATE("Base ",$M13," ",$K13," noches"))) | O13: =IFERROR((VLOOKUP($N13,Pricing!$D$2:$E$43,2,FALSE)),"")
A14: =+IF(D14="","",CONCATENATE("GBL 00",Mantenedor!E13)) | L14: =IF(K14="","",(J14+K14)) | N14: =IF($K14="","",IF($K14=1,CONCATENATE("Base ",$M14," ",$K14," noche"),CONCATENATE("Base ",$M14," ",$K14," noches"))) | O14: =IFERROR((VLOOKUP($N14,Pricing!$D$2:$E$43,2,FALSE)),"")
A15: =+IF(D15="","",CONCATENATE("GBL 00",Mantenedor!E14)) | L15: =IF(K15="","",(J15+K15)) | N15: =IF($K15="","",IF($K15=1,CONCATENATE("Base ",$M15," ",$K15," noche"),CONCATENATE("Base ",$M15," ",$K15," noches"))) | O15: =IFERROR((VLOOKUP($N15,Pricing!$D$2:$E$43,2,FALSE)),"")
... A502: =+IF(D502="","",CONCATENATE("GBL 00",Mantenedor!E501)) | L502: =IF(K502="","",(J502+K502)) | N502: =IF($K502="","",IF($K502=1,CONCATENATE("Base ",$M502," ",$K502," noche"),CONCATENATE("Base ",$M502," ",$K502," noches"))) | O502: =IFERROR((VLOOKUP($N502,Pricing!$D$2:$E$43,2,FALSE)),"")
A503: x | D503: x | F503: x | I503: x | J503: x | K503: x | L503: x | M503: x | N503: x | O503: x | P503: x | Q503: x | R503: x | S503: x | T503: x | U503: x | V503: x | W503: x | AA503: x | AB503: x | AC503: x | AD503: x | AE503: x | AF503: x | AG503: x | AH503: x | AI503: x

Sheet CHECK-IN
B3: N˚ Grupo
B5: Información de Grupo
B6: Información Personal | G6: Información del Programa
B7: N˚ Pasajero | C7: Nombre completo | D7: Número de contacto | E7: Mail | F7: Género | G7: Base | H7: Check-In | I7: N˚ Noches | J7: Check-Out | K7: Pescador/Non Angles
B8: Pasajero N˚1 | C8: Francisco frias | D8: 12312413 | E8: {=IF(#REF!="","",(_xlfn.IFS(#REF!="No",#REF!="",#REF!="Si",#REF!="")))} -> #REF! | G8: Single | J8: =+H8+I8 -> 0 | K8: Pescador
B9: Pasajero N˚2 | G9: Single | J9: =+H9+I9 -> 0 | K9: Pescador
B10: Pasajero N˚3 | G10: Doble | J10: =+H10+I10 -> 0 | K10: Pescador
A11: Si | B11: Pasajero N˚4 | G11: Doble | J11: =+H11+I11 -> 0 | K11: Pescador
A12: Si | B12: Pasajero N˚5 | G12: Single | J12: =+H12+I12 -> 0 | K12: Pescador
A13: Si | B13: Pasajero N˚6 | K13: Pescador
A14: No | B14: Pasajero N˚7 | K14: Pescador
A15: No | B15: Pasajero N˚8 | K15: Pescador
A16: No | B16: Pasajero N˚9 | K16: Pescador
B17: Pasajero N˚10 | K17: Pescador

Sheet COBRANZA
B4: N˚ Grupo
B5: Fecha de reserva
B6: Check-In
B8: Reserva
B9: Plazo | C9: Fecha
B10: Reserva - 105 días
B11: Reserva - 90 días
B12: Reserva - 75 días
B13: Reserva - 60 días
B14: Reserva - 45 días
B15: Reserva - 30 días
B16: Reserva - Llamar
B18: Saldo
B19: Plazo | C19: Fecha
B20: Saldo - 45 días
B21: Saldo - 30 días
B22: Saldo - 15 días
B23: Saldo - 7 días
B24: Saldo - Llamar

Sheet EJEMPLO JIP
A1: GREEN BAKER LODGE | C1: 45929 | F1: CELDAS | I1: DEBEN SER LLENADAS MANUALMENTE
A2: AREA PESCA | F2: CELDAS | I2: DEBEN SER LLENADAS MANUALMENTE
A3: GESTION DE RESERVA
A5: GRUPO | B5: RESERVA
B6: - fecha reserva | C6: 45853
B7: - nombre contacto | C7: Jorge Icaza Perez | E7: Non Angler | F7: Madi Vega | I7: NA
B8: - mail | C8: jicaza@vecta.cl | E8: Non Angler | F8: NN
B9: - telefono | C9: 9 9318 3704 | E9: Non Angler | F9: NN
B10: - valor bruto programa | C10: =+precio!B6 -> 0 | I10: =COUNT(I7:I9) -> 0
B11: - check in | C11: 46006
B12: - check out | C12: =+C11+C13 -> 46012
B13: - numero de dias | C13: 6
D14: VALOR DEL PROGRAMA NACIONAL
B15: PASAJEROS | C15: Mail / Celular | D15: Noches | E15: precio | F15: dcto | H15: a pagar | I15: V°B°
A16: 0 | B16: Martin Icaza Gana | D16: =+C13 -> 6 | E16: =+precio!B6 -> 0 | F16: 0.2 | H16: =+E16*(1-F16) -> 0 | I16: FSN | K16: =17*200 -> 3400
A17: 0 | B17: Alejandra Icaza Gana | D17: =+D16 -> 6 | E17: =+precio!B6 -> 0 | F17: 1 | H17: 0 | I17: =+I16 -> FSN
B18: Javier Icaza Gana | D18: =+D17 -> 6 | E18: =+precio!B6 -> 0 | F18: 0.2 | H18: =+E18*(1-F18) -> 0 | I18: =+I17 -> FSN
B19: Madi Vega | D19: =+D18 -> 6 | E19: =+precio!B7 -> 0 | F19: 0.2 | I19: =+I18 -> FSN
B20: Coni Osorio | D20: =+D19 -> 6 | E20: =+precio!B8 -> 0 | F20: 0.2 | I20: =+I19 -> FSN
B21: Anibal Icaza Gana | D21: =+D18 -> 6 | E21: =+precio!B6 -> 0 | F21: =+F18 -> 0.2 | H21: =+E21*(1-F21) -> 0 | I21: =+I18 -> FSN
B22: Total Cañas | D22: =SUM(D16:D21) -> 36 | E22: =+(D22-F22)/D22 -> 1 | F22: =SUM(H16:H21) -> 0
J24: ENVIO | K24: PAGO RESERVA (50%) | M24: PAGO SALDO (50%) | O24: FECHA | P24: MONTO | Q24: MEDIO | R24: ADEUDADO | S24: ADEUDADO | T24: OBSERVACIONES
A25: GRUPO | B25: RESERVA | J25: RESPUESTA | K25: PLAZO | L25: FECHA | M25: PLAZO | N25: FECHA | O25: PAGO | P25: BRUTO | Q25: PAGO | R25: ABONO | S25: TOTAL
B26: - fecha reserva | F26: nombre | H26: CODIGO AA | K26: reserva + 30 | M26: check in - 45 | N26: =+C31-45 -> 45950 | R26: =+(F41/2)-P26 -> #DIV/0! | S26: =+F41-P26 -> #DIV/0!
B27: - nombre contacto | C27: Jose luis Rodriguez casanueva | E27: Non Angler | K27: reserva + 45 | M27: check in - 30 | N27: =+C31-30 -> 45965
B28: - mail | C28: rafael.loyoladominguez@gmail.com | E28: Non Angler | K28: reserva + 60 | M28: check in - 15 | N28: =+C31-15 -> 45980
B29: - telefono | E29: Non Angler | K29: reserva + 75 | M29: check in - 7 | N29: =+C31-7 -> 45988
B30: - valor bruto programa | H30: Total | K30: reserva + 90 | M30: llamar
B31: - check in | C31: 45995 | E31: identificar NON ANGLER al final de lista de pasajeros | K31: reserva + 105
B32: - check out | C32: =+C31+C33 -> 45999 | K32: llamar
B33: - numero de dias | C33: 4
D34: VALOR DEL PROGRAMA NACIONAL (CON IVA)
B35: PASAJEROS | C35: Mail / Celular | D35: Noches | E35: precio lista | F35: dcto % | G35: comision % | H35: a pagar | I35: V°B°
A36: 1 | B36: Jose luis Rodriguez casanueva | D36: =+#REF! -> #REF! | E36: =+C30 -> 0 | F36: 0 | G36: 0
A37: =+A36+1 -> 2 | B37: Borja Rodriguez Rios | D37: =+#REF! -> #REF! | F37: =+F36 -> 0
A38: =+A37+1 -> 3 | B38: Ignacio Rodiguez Rios | D38: =+#REF! -> #REF! | F38: =+F37 -> 0
A39: =+A38+1 -> 4 | B39: Cristian Fabres Ruiz | D39: =+#REF! -> #REF! | F39: =+F38 -> 0
A40: =+A39+1 -> 5 | B40: Rafael Loyola Dominguez | D40: =+#REF! -> #REF! | F40: =+F39 -> 0
B41: Total Cañas | D41: =SUM(D36:D40) -> #REF! | F41: =+(E41-H41)/E41 -> #DIV/0!
A44: GESTION DE COBRANZA
...

Sheet Pricing
A1: Base | B1: N° Días | C1: Noches | D1: Texto | E1: Valor bruto
A2: Base single | B2: 1 | C2: 1 noche | D2: =+CONCATENATE(A2," ",C2) -> Base single 1 noche | E2: 770000
A3: Base doble | B3: 1 | C3: 1 noche | D3: =+CONCATENATE(A3," ",C3) -> Base doble 1 noche | E3: 550000
A4: Non angler nacional | B4: 1 | C4: 1 noche | D4: =+CONCATENATE(A4," ",C4) -> Non angler nacional 1 noche | E4: 550000 | G4: Dia 1 traslado | H4: Dia 1 mediodia | I4: Día 2 full | J4: Día 3 full | K4: Día 4 full | L4: Día 5 full | M4: Día 6 full | N4: Día 7 full | O4: Día 8 full | P4: Día 9 full | Q4: Día 10 full | R4: Día 11 full | S4: Día 12 full | T4: Día 13 full | U4: Día 14 full | V4: Día 15 traslado
A5: Base single | B5: =+B2+1 -> 2 | C5: 2 noches | D5: =+CONCATENATE(A5," ",C5) -> Base single 2 noches | E5: 1330000 | G5: 200000 | H5: 350000 | I5: 400000 | J5: 400000 | K5: 400000 | L5: 400000 | M5: 400000 | N5: 400000 | O5: 400000 | P5: 400000 | Q5: 400000 | R5: 400000 | S5: 400000 | T5: 400000 | U5: 400000 | V5: 200000
A6: Base doble | B6: =+B3+1 -> 2 | C6: 2 noches | D6: =+CONCATENATE(A6," ",C6) -> Base doble 2 noches | E6: 950000 | I6: 1 noche | J6: 2 noches | K6: 3 noches | L6: 4 noches | M6: 5 noches | N6: 6 noches | O6: 7 noches | P6: 8 noches | Q6: 9 noches | R6: 10 noches | S6: 11 noches | T6: 12 noches | U6: 13 noches | V6: 14 noches
A7: Non angler nacional | B7: =+B4+1 -> 2 | C7: 2 noches | D7: =+CONCATENATE(A7," ",C7) -> Non angler nacional 2 noches | E7: 950000 | G7: Base single | I7: 770000 | J7: 1330000 | K7: 1890000 | L7: 2450000 | M7: 3010000 | N7: 3570000 | O7: 4130000 | P7: 4690000 | Q7: 5250000 | R7: 5810000 | S7: 6370000 | T7: 6930000 | U7: 7490000 | V7: 8050000
A8: Base single | B8: =+B5+1 -> 3 | C8: 3 noches | D8: =+CONCATENATE(A8," ",C8) -> Base single 3 noches | E8: 1890000 | G8: Base doble | I8: 550000 | J8: 950000 | K8: 1350000 | L8: 1750000 | M8: 2150000 | N8: 2550000 | O8: 2950000 | P8: 3350000 | Q8: 3750000 | R8: 4150000 | S8: 4550000 | T8: 4950000 | U8: 5350000 | V8: 5750000
A9: Base doble | B9: =+B6+1 -> 3 | C9: 3 noches | D9: =+CONCATENATE(A9," ",C9) -> Base doble 3 noches | E9: 1350000 | G9: Non angler nacional | I9: 550000 | J9: 950000 | K9: 1350000 | L9: 1750000 | M9: 2150000 | N9: 2550000 | O9: 2950000 | P9: 3350000 | Q9: 3750000 | R9: 4150000 | S9: 4550000 | T9: 4950000 | U9: 5350000 | V9: 5750000
A10: Non angler nacional | B10: =+B7+1 -> 3 | C10: 3 noches | D10: =+CONCATENATE(A10," ",C10) -> Non angler nacional 3 noches | E10: 1350000 | L10: 0.09375
A11: Base single | B11: =+B8+1 -> 4 | C11: 4 noches | D11: =+CONCATENATE(A11," ",C11) -> Base single 4 noches | E11: 2450000 | G11: TARIFA x PERSONA | H11: USD
A12: Base doble | B12: =+B9+1 -> 4 | C12: 4 noches | D12: =+CONCATENATE(A12," ",C12) -> Base doble 4 noches | E12: 1750000 | I12: 1 noche | J12: 2 noches | K12: 3 noches | L12: 4 noches | M12: 5 noches | N12: 6 noches | O12: 7 noches | P12: 8 noches | Q12: 9 noches | R12: 10 noches | S12: 11 noches | T12: 12 noches | U12: 13 noches | V12: 14 noches
A13: Non angler nacional | B13: =+B10+1 -> 4 | C13: 4 noches | D13: =+CONCATENATE(A13," ",C13) -> Non angler nacional 4 noches | E13: 1750000 | G13: Día 1 traslado | H13: Día 1; 1/2 dia | I13: Día 2 full | J13: Día 3 full | K13: Día 4 full | L13: Día 5 full | M13: Día 6 full | N13: Día 7 full | O13: Día 8 full | P13: Día 9 full | Q13: Día 10 full | R13: Día 11 full | S13: Día 12 full | T13: Día 13 full | U13: Día 14 full | V13: Día 15 traslado
A14: Base single | B14: =+B11+1 -> 5 | C14: 5 noches | D14: =+CONCATENATE(A14," ",C14) -> Base single 5 noches | E14: 3010000 | G14: 350 | H14: 1000 | I14: 900 | J14: 900 | K14: 900 | L14: 900 | M14: 900 | N14: 900 | O14: 900 | P14: 900 | Q14: 900 | R14: 900 | S14: 900 | T14: 900 | U14: 900 | V14: 350
A15: Base doble | B15: =+B12+1 -> 5 | C15: 5 noches | D15: =+CONCATENATE(A15," ",C15) -> Base doble 5 noches | E15: 2150000 | I15: 1 noche | J15: 2 noches | K15: 3 noches | L15: 4 noches | M15: 5 noches | N15: 6 noches | O15: 7 noches | P15: 8 noches | Q15: 9 noches | R15: 10 noches | S15: 11 noches | T15: 12 noches | U15: 13 noches | V15: 14 noches
A16: Non angler nacional | B16: =+B13+1 -> 5 | C16: 5 noches | D16: =+CONCATENATE(A16," ",C16) -> Non angler nacional 5 noches | E16: 2150000 | G16: Base single | I16: 1890 | J16: 3150 | K16: 4410 | L16: 5670 | M16: 6930 | N16: 8190 | O16: 9450 | P16: 10710 | Q16: 11970 | R16: 13230 | S16: 14490 | T16: 15750 | U16: 17010 | V16: 18270
A17: Base single | B17: =+B14+1 -> 6 | C17: 6 noches | D17: =+CONCATENATE(A17," ",C17) -> Base single 6 noches | E17: 3570000 | G17: Base doble | I17: 1350 | J17: 2250 | K17: 3150 | L17: 4050 | M17: 4950 | N17: 5850 | O17: 6750 | P17: 7650 | Q17: 8550 | R17: 9450 | S17: 10350 | T17: 11250 | U17: 12150 | V17: 13050
A18: Base doble | B18: =+B15+1 -> 6 | C18: 6 noches | D18: =+CONCATENATE(A18," ",C18) -> Base doble 6 noches | E18: 2550000 | G18: Non angler | I18: 945 | J18: 1575 | K18: 2205 | L18: 2835 | M18: 3465 | N18: 4095 | O18: 4725 | P18: 5355 | Q18: 5985 | R18: 6615 | S18: 7245 | T18: 7875 | U18: 8505 | V18: 9135
A19: Non angler nacional | B19: =+B16+1 -> 6 | C19: 6 noches | D19: =+CONCATENATE(A19," ",C19) -> Non angler nacional 6 noches | E19: 2550000 | O19: 0.10655738
A20: Base single | B20: =+B17+1 -> 7 | C20: 7 noches | D20: =+CONCATENATE(A20," ",C20) -> Base single 7 noches | E20: 4130000 | G20: TARIFAS DÍA DE PESCA (BASE DOBLE)
A21: Base doble | B21: =+B18+1 -> 7 | C21: 7 noches | D21: =+CONCATENATE(A21," ",C21) -> Base doble 7 noches | E21: 2950000 | I21: $ | J21: USD
A22: Non angler nacional | B22: =+B19+1 -> 7 | C22: 7 noches | D22: =+CONCATENATE(A22," ",C22) -> Non angler nacional 7 noches | E22: 2950000 | G22: 1/2 DÍA | I22: 350000 | J22: 390 | K22: 0.16666667 | L22: * 4 HORAS DE PESCA. INCLUYE AGUA Y BEBIDAS NO ALCOHÓLICAS.
A23: Base single | B23: =+B20+1 -> 8 | C23: 8 noches | D23: =+CONCATENATE(A23," ",C23) -> Base single 8 noches | E23: 4690000 | G23: DIA COMPLETO | I23: 500000 | J23: 550 | K23: 0.11111111 | L23: * 8 HORAS DE PESCA. INCLUYE BOX LUNCH.
A24: Base doble | B24: =+B21+1 -> 8 | C24: 8 noches | D24: =+CONCATENATE(A24," ",C24) -> Base doble 8 noches | E24: 3350000
A25: Non angler nacional | B25: =+B22+1 -> 8 | C25: 8 noches | D25: =+CONCATENATE(A25," ",C25) -> Non angler nacional 8 noches | E25: 3350000 | G25: 20% Comisión Venta Nacional
A26: Base single | B26: =+B23+1 -> 9 | C26: 9 noches | D26: =+CONCATENATE(A26," ",C26) -> Base single 9 noches | E26: 5250000 | G26: 20% Comisión Venta Internacional
A27: Base doble | B27: =+B24+1 -> 9 | C27: 9 noches | D27: =+CONCATENATE(A27," ",C27) -> Base doble 9 noches | E27: 3750000
A28: Non angler nacional | B28: =+B25+1 -> 9 | C28: 9 noches | D28: =+CONCATENATE(A28," ",C28) -> Non angler nacional 9 noches | E28: 3750000 | G28: Hosted Trips | H28: Sobre 5 Clientes
A29: Base single | B29: =+B26+1 -> 10 | C29: 10 noches | D29: =+CONCATENATE(A29," ",C29) -> Base single 10 noches | E29: 5810000
A30: Base doble | B30: =+B27+1 -> 10 | C30: 10 noches | D30: =+CONCATENATE(A30," ",C30) -> Base doble 10 noches | E30: 4150000
A31: Non angler nacional | B31: =+B28+1 -> 10 | C31: 10 noches | D31: =+CONCATENATE(A31," ",C31) -> Non angler nacional 10 noches | E31: 4150000
A32: Base single | B32: =+B29+1 -> 11 | C32: 11 noches | D32: =+CONCATENATE(A32," ",C32) -> Base single 11 noches | E32: 6370000
A33: Base doble | B33: =+B30+1 -> 11 | C33: 11 noches | D33: =+CONCATENATE(A33," ",C33) -> Base doble 11 noches | E33: 4550000
A34: Non angler nacional | B34: =+B31+1 -> 11 | C34: 11 noches | D34: =+CONCATENATE(A34," ",C34) -> Non angler nacional 11 noches | E34: 4550000
A35: Base single | B35: =+B32+1 -> 12 | C35: 12 noches | D35: =+CONCATENATE(A35," ",C35) -> Base single 12 noches | E35: 6930000
A36: Base doble | B36: =+B33+1 -> 12 | C36: 12 noches | D36: =+CONCATENATE(A36," ",C36) -> Base doble 12 noches | E36: 4950000
A37: Non angler nacional | B37: =+B34+1 -> 12 | C37: 12 noches | D37: =+CONCATENATE(A37," ",C37) -> Non angler nacional 12 noches | E37: 4950000
A38: Base single | B38: =+B35+1 -> 13 | C38: 13 noches | D38: =+CONCATENATE(A38," ",C38) -> Base single 13 noches | E38: 7490000
A39: Base doble | B39: =+B36+1 -> 13 | C39: 13 noches | D39: =+CONCATENATE(A39," ",C39) -> Base doble 13 noches | E39: 5350000
A40: Non angler nacional | B40: =+B37+1 -> 13 | C40: 13 noches | D40: =+CONCATENATE(A40," ",C40) -> Non angler nacional 13 noches | E40: 5350000
...

Sheet precio
A1: TARIFA x PERSONA | B1: $
A3: Dia 1 traslado | B3: Dia 1 mediodia | C3: Día 2 full | D3: Día 3 full | E3: Día 4 full | F3: Día 5 full | G3: Día 6 full | H3: Día 7 full | I3: Día 8 full | J3: Día 9 full | K3: Día 10 full | L3: Día 11 full | M3: Día 12 full | N3: Día 13 full | O3: Día 14 full | P3: Día 15 traslado
A4: 200000 | B4: 350000 | C4: 400000 | D4: =+C4 -> 400000 | E4: =+D4 -> 400000 | F4: =+E4 -> 400000 | G4: =+F4 -> 400000 | H4: =+G4 -> 400000 | I4: =+H4 -> 400000 | J4: =+I4 -> 400000 | K4: =+J4 -> 400000 | ... O4: =+N4 -> 400000 | P4: 200000
C5: 1 noche | D5: 2 noches | E5: 3 noches | F5: 4 noches | G5: 5 noches | H5: 6 noches | I5: 7 noches | J5: 8 noches | K5: 9 noches | L5: 10 noches | M5: 11 noches | N5: 12 noches | O5: 13 noches | P5: 14 noches
A6: Base single | C6: =+C7*1.4 -> 770000 | D6: =+D7*1.4 -> 1330000 | E6: =+E7*1.4 -> 1890000 | F6: =+F7*1.4 -> 2450000 | G6: =+G7*1.4 -> 3010000 | H6: =+H7*1.4 -> 3570000 | I6: =+I7*1.4 -> 4130000 | J6: =+J7*1.4 -> 4690000 | ... P6: =+P7*1.4 -> 8050000
A7: Base doble | C7: =($A4/2)+B4+($P4/2) -> 550000 | D7: =($A4/2)+C4+B4+($P4/2) -> 950000 | E7: =($A4/2)+B4+D4+C4+($P4/2) -> 1350000 | F7: =($A4/2)+B4+C4+E4+D4+($P4/2) -> 1750000 | G7: =($A4/2)+B4+C4+D4+F4+E4+($P4/2) -> 2150000 | H7: =($A4/2)+B4+C4+D4+E4+G4+F4+($P4/2) -> 2550000 | I7: =($A4/2)+B4+C4+D4+E4+F4+H4+G4+($P4/2) -> 2950000 | J7: =($A4/2)+B4+C4+D4+E4+F4+G4+I4+H4+($P4/2) -> 3350000 | K7: =($A4/2)+B4+C4+D4+E4+F4+G4+H4+J4+I4+($P4/2) -> 3750000 | L7: =($A4/2)+B4+C4+D4+E4+F4+G4+H4+I4+K4+J4+($P4/2) -> 4150000 | M7: =($A4/2)+B4+C4+D4+E4+F4+G4+H4+I4+J4+L4+K4+($P4/2) -> 4550000 | N7: =($A4/2)+B4+C4+D4+E4+F4+G4+H4+I4+J4+K4+M4+L4+($P4/2) -> 4950000 | O7: =($A4/2)+B4+C4+D4+E4+F4+G4+H4+I4+J4+K4+L4+N4+M4+($P4/2) -> 5350000 | P7: =($A4/2)+B4+C4+D4+E4+F4+G4+H4+I4+J4+K4+L4+M4+O4+N4+($P4/2) -> 5750000
A8: Non angler nacional | C8: =+C7 -> 550000 | D8: =+D7 -> 950000 | E8: =+E7 -> 1350000 | F8: =+F7 -> 1750000 | G8: =+G7 -> 2150000 | H8: =+H7 -> 2550000 | I8: =+I7 -> 2950000 | J8: =+J7 -> 3350000 | ... P8: =+P7 -> 5750000
F9: 0.09375
A10: TARIFA x PERSONA | B10: USD
C11: 1 noche | D11: 2 noches | E11: 3 noches | F11: 4 noches | G11: 5 noches | H11: 6 noches | I11: 7 noches | J11: 8 noches | K11: 9 noches | L11: 10 noches | M11: 11 noches | N11: 12 noches | O11: 13 noches | P11: 14 noches
A12: Día 1 traslado | B12: Día 1; 1/2 dia | C12: Día 2 full | D12: Día 3 full | E12: Día 4 full | F12: Día 5 full | G12: Día 6 full | H12: Día 7 full | I12: Día 8 full | J12: Día 9 full | K12: Día 10 full | L12: Día 11 full | M12: Día 12 full | N12: Día 13 full | O12: Día 14 full | P12: Día 15 traslado
A13: 350 | B13: 1000 | C13: 900 | D13: =+C13 -> 900 | E13: =+D13 -> 900 | F13: =+E13 -> 900 | G13: =+F13 -> 900 | H13: =+G13 -> 900 | I13: =+H13 -> 900 | J13: =+I13 -> 900 | K13: =+J13 -> 900 | ... O13: =+N13 -> 900 | P13: =+A13 -> 350
C14: 1 noche | D14: 2 noches | E14: 3 noches | F14: 4 noches | G14: 5 noches | H14: 6 noches | I14: 7 noches | J14: 8 noches | K14: 9 noches | L14: 10 noches | M14: 11 noches | N14: 12 noches | O14: 13 noches | P14: 14 noches
A15: Base single | C15: =+C16*1.4 -> 1890 | D15: =+D16*1.4 -> 3150 | E15: =+E16*1.4 -> 4410 | F15: =+F16*1.4 -> 5670 | G15: =+G16*1.4 -> 6930 | H15: =+H16*1.4 -> 8190 | I15: =+I16*1.4 -> 9450 | J15: =+J16*1.4 -> 10710 | ... P15: =+P16*1.4 -> 18270
A16: Base doble | C16: =($A13/2)+B13+($P13/2) -> 1350 | D16: =($A13/2)+C13+B13+($P13/2) -> 2250 | E16: =($A13/2)+B13+D13+C13+($P13/2) -> 3150 | F16: =($A13/2)+B13+C13+E13+D13+($P13/2) -> 4050 | G16: =($A13/2)+B13+C13+D13+F13+E13+($P13/2) -> 4950 | H16: =($A13/2)+B13+C13+D13+E13+G13+F13+($P13/2) -> 5850 | I16: =($A13/2)+B13+C13+D13+E13+F13+H13+G13+($P13/2) -> 6750 | J16: =($A13/2)+B13+C13+D13+E13+F13+G13+I13+H13+($P13/2) -> 7650 | K16: =($A13/2)+B13+C13+D13+E13+F13+G13+H13+J13+I13+($P13/2) -> 8550 | L16: =($A13/2)+B13+C13+D13+E13+F13+G13+H13+I13+K13+J13+($P13/2) -> 9450 | M16: =($A13/2)+B13+C13+D13+E13+F13+G13+H13+I13+J13+L13+K13+($P13/2) -> 10350 | N16: =($A13/2)+B13+C13+D13+E13+F13+G13+H13+I13+J13+K13+M13+L13+($P13/2) -> 11250 | O16: =($A13/2)+B13+C13+D13+E13+F13+G13+H13+I13+J13+K13+L13+N13+M13+($P13/2) -> 12150 | P16: =($A13/2)+B13+C13+D13+E13+F13+G13+H13+I13+J13+K13+L13+M13+O13+N13+($P13/2) -> 13050
A17: Non angler | C17: =+C16*0.7 -> 945 | D17: =+D16*0.7 -> 1575 | E17: =+E16*0.7 -> 2205 | F17: =+F16*0.7 -> 2835 | G17: =+G16*0.7 -> 3465 | H17: =+H16*0.7 -> 4095 | I17: =+I16*0.7 -> 4725 | J17: =+J16*0.7 -> 5355 | ... P17: =+P16*0.7 -> 9135
I18: 0.10655738
A19: TARIFAS DÍA DE PESCA (BASE DOBLE)
C20: $ | D20: USD
A21: 1/2 DÍA | C21: 350000 | D21: 390 | E21: 0.16666667 | F21: * 4 HORAS DE PESCA. INCLUYE AGUA Y BEBIDAS NO ALCOHÓLICAS.
A22: DIA COMPLETO | C22: 500000 | D22: 550 | E22: 0.11111111 | F22: * 8 HORAS DE PESCA. INCLUYE BOX LUNCH.
A24: 20% Comisión Venta Nacional
A25: 20% Comisión Venta Internacional
A27: Hosted Trips | B27: Sobre 5 Clientes

Sheet Mantenedor
A1: Contacto | B1: N° Días / Pasajero | C1: Tipo | D1: Base | E1: N° Cliente | F1: Extranjero | G1: Género
A2: Si | B2: 1 | C2: Pescador | D2: Single | E2: 1 | F2: Nacional | G2: Masculino
A3: No | B3: 2 | C3: Non Angler | D3: Doble | E3: 2 | F3: Extranjero | G3: Femenino
B4: 3 | D4: Host | E4: 3
B5: 4 | E5: 4
B6: 5 | E6: 5
B7: 6 | E7: 6
B8: 7 | E8: 7
B9: 8 | E9: 8
B10: 9 | E10: 9
B11: 10 | E11: 10
B12: 11 | E12: 11
B13: 12 | E13: 12
B14: 13 | E14: 13
B15: 14 | E15: 14
B16: 15 | E16: 15
... B21: 20 | E21: 20
E22: 21
E23: 22
E24: 23
E25: 24
E26: 25
E27: 26
E28: 27
E29: 28
E30: 29
E31: 30
E32: 31
E33: 32
... E501: 500
